Workbook

Sheet README
A1: Prefs database - layered reconciliation
A2: Built 2026-08-21 from prefsTEST.xlsx (809 issue rows, 354 parent blocks) + the QOLpaste sheet (1,004 securities).
A4: WHAT THIS IS
A5: Your current required yield / normal price / discount / total-return-potential, next to recomputed values,
A6: one layer of change at a time. Each layer has its own delta column so you can accept or reject it on its own.
A8: L1 wiring fixed Same base yield, same penalty each row already used. Isolates pure bug impact.
A9: L2 penalties unified One scheme from the Inputs tab instead of the two that coexist today.
A10: L3 payment derived Annual amount = coupon x par everywhere, instead of 106 different formulas.
A11: NOTE: L3 moves nothing. In most rows the coupon column is itself defined as amount/par, so the two
A12: conventions cannot disagree - they are the same number twice. Standardizing here is a maintainability
A13: fix, not a correction. The independent check on coupon and amount is L5, against QuantumOnline.
A14: L4 market-cap ladder Base yield keyed off parent market cap instead of parent price.
... A45: Zero-Base Parents the 62 blocks whose valuation is broken because the parent did not quote

Sheet Inputs
A1: MASTER INPUTS
A2: Every yellow cell is an input. Edit it and the Reconciliation tab recalculates.
A4: Rates
A5: Treasury | B5: 0.04 | D5: Was 'T-Z'!E1 in the old workbook.
A6: SOFR | C6: <- needs value | D6: REPLACES the dead LIBOR cell (old value 0.75%). Needs a feed - see notes.
A8: Required-yield adjustments
A9: QDI switch | B9: -1 | D9: Sign on the QDI adjustment. -1 = QDI issues get a LOWER required yield.
A10: QDI adjustment (relative) | B10: 0.05 | D10: Applied as base x this x switch. 5% of base, not 5 points.
A12: Structure adjustment (absolute) | D12: Replaces the nested IFs. Add rows freely.
A13: PREFERRED | B13: 0
A14: BABY_BOND | B14: -0.005 | D14: Was "debt" -0.50%. The competing scheme used -0.75%.
A15: TRUPS | B15: -0.005 | D15: Was "tp"/"trups", inherited the debt adjustment.
A17: Coupon-type adjustment (absolute) | D17: New axis. All zero until you decide otherwise.
A18: FIXED | B18: 0
A19: FIX_TO_FLOAT | B19: 0
A20: FLOATER | B20: 0
A21: RESET | B21: 0
A22: VARIABLE | B22: 0
A23: CONVERTIBLE | B23: 0
A24: MAND_CONVERT | B24: 0
A26: Market-cap -> base yield ladder
A27: Upper bound ($mm) | B27: Base yield | D27: Replaces the old PARENT PRICE ladder: <=$10 -> 10%, $10-15 -> 9%, $15-20 -> 8.5%, >$20 -> 8%
A28: 250 | B28: 0.1
A29: 1000 | B29: 0.09
A30: 5000 | B30: 0.085
A31: 20000 | B31: 0.08
A32: 99999999 | B32: 0.075
A34: NOTES
A35: 1. Baseline columns (R/S/T/U as they sit today) are HARDCODED cached values from prefsTEST.xlsx.
A36: They cannot be recomputed here - they came from the RealTick RTD feed. Price is a snapshot from the same source.
A37: 2. Market cap is the cached RealTick value on each parent row, parsed from the "1.2 B" / "500 M" string.
A38: 62 parents show 0 because RealTick returned nothing for the parent at all. Those need a real market cap.
A39: 3. Every layer column IS a live formula against this tab. Retune a yellow cell and the deltas move.
A40: 4. Cumulative is deliberately NOT an adjustment - it is a display flag only.

Sheet Reconciliation
A1: CONTEXT | R1: AS IT SITS TODAY | V1: L1 wiring fixed | AB1: L2 penalties unified | AG1: L3 payment derived | AL1: L4 market-cap ladder | AT1: L5 facts refreshed | BC1: SUMMARY
A2: Sheet | B2: Src Row | C2: Symbol | D2: Parent | E2: Parent Name | F2: Mkt Cap ($mm) | G2: Structure | H2: Coupon Type | I2: QDI | J2: Freq | K2: Per/Yr | L2: Par (wb) | M2: Coupon (wb) | N2: Ann Amt (wb) | O2: Price | P2: Exception | Q2: Group Base | R2: R cur | S2: S cur | T2: T cur | U2: U cur | V2: hist adj | W2: R L1 | X2: S L1 | Y2: T L1 | Z2: U L1 | AA2: dU L1 | AB2: R L2 | AC2: S L2 | AD2: T L2 | AE2: U L2 | AF2: dU L2 | AG2: Ann Amt L3 | AH2: S L3 | AI2: T L3 | AJ2: U L3 | AK2: dU L3 | AL2: Base mktcap | AM2: Base override | AN2: Base eff | AO2: R L4 | AP2: S L4 | AQ2: T L4 | AR2: U L4 | AS2: dU L4 | AT2: Par QOL | AU2: Ann QOL | AV2: Par eff | AW2: Ann eff | AX2: R L5 | AY2: S L5 | AZ2: T L5 | BA2: U L5 | BB2: dU L5 | BC2: TOTAL dU | BD2: Flags
A3: A-C | B3: 7 | C3: AAIN | D3: AAIC | E3: na | G3: PREFERRED | H3: FIXED | I3: no | J3: Q | K3: 4 | L3: 25 | M3: 0.06 | N3: 1.5 | O3: 0 | P3: OK | Q3: 0 | R3: 0 | V3: 0 | W3: =IF(N(Q3)=0,"",Q3+IF(I3="yes",Q3*Inputs!$B$10*Inputs!$B$9,0)+V3) | X3: =IF(OR(N(W3)<=0,N(N3)=0,N(L3)=0),"",MIN(L3,N3/W3)) | Y3: =IF(OR(X3="",N(O3)=0),"",X3/O3-1) | Z3: =IF(OR(Y3="",N(O3)=0),"",Y3+N3/O3) | AA3: =IF(OR(Z3="",N(U3)=0),"",Z3-U3) | AB3: =IF(N(Q3)=0,"",Q3+IF(I3="yes",Q3*Inputs!$B$10*Inputs!$B$9,0)+IFERROR(INDEX(Inputs!$B$13:$B$15,MATCH(G3,Inputs!$A$13:$A$15,0)),0)+IFERROR(INDEX(Inputs!$B$18:$B$24,MATCH(H3,Inputs!$A$18:$A$24,0)),0)) | AC3: =IF(OR(N(AB3)<=0,N(N3)=0,N(L3)=0),"",MIN(L3,N3/AB3)) | AD3: =IF(OR(AC3="",N(O3)=0),"",AC3/O3-1) | AE3: =IF(OR(AD3="",N(O3)=0),"",AD3+N3/O3) | AF3: =IF(OR(AE3="",N(Z3)=0),"",AE3-Z3) | AG3: =IF(AND(N(M3)>0,N(L3)>0),M3*L3,N3) -> 1.5 | AH3: =IF(OR(N(AB3)<=0,N(AG3)=0,N(L3)=0),"",MIN(L3,AG3/AB3)) | AI3: =IF(OR(AH3="",N(O3)=0),"",AH3/O3-1) | AJ3: =IF(OR(AI3="",N(O3)=0),"",AI3+AG3/O3) | AK3: =IF(OR(AJ3="",N(AE3)=0),"",AJ3-AE3) | AL3: =IF(N(F3)=0,"",INDEX(Inputs!$B$28:$B$32,IFERROR(MATCH(F3,Inputs!$A$28:$A$32,1),0)+1)) | AN3: =IF(N(AM3)>0,AM3,AL3) | AO3: =IF(N(AN3)=0,"",AN3+IF(I3="yes",AN3*Inputs!$B$10*Inputs!$B$9,0)+IFERROR(INDEX(Inputs!$B$13:$B$15,MATCH(G3,Inputs!$A$13:$A$15,0)),0)+IFERROR(INDEX(Inputs!$B$18:$B$24,MATCH(H3,Inputs!$A$18:$A$24,0)),0)) | AP3: =IF(OR(N(AO3)<=0,N(AG3)=0,N(L3)=0),"",MIN(L3,AG3/AO3)) | AQ3: =IF(OR(AP3="",N(O3)=0),"",AP3/O3-1) | AR3: =IF(OR(AQ3="",N(O3)=0),"",AQ3+AG3/O3) | AS3: =IF(OR(AR3="",N(AJ3)=0),"",AR3-AJ3) | AV3: =IF(N(AT3)>0,AT3,L3) -> 25 | AW3: =IF(AND(N(M3)>0,N(AV3)>0),M3*AV3,IF(N(AU3)>0,AU3,N3)) -> 1.5 | AX3: =IF(N(AN3)=0,"",AN3+IF(I3="yes",AN3*Inputs!$B$10*Inputs!$B$9,0)+IFERROR(INDEX(Inputs!$B$13:$B$15,MATCH(G3,Inputs!$A$13:$A$15,0)),0)+IFERROR(INDEX(Inputs!$B$18:$B$24,MATCH(H3,Inputs!$A$18:$A$24,0)),0)) | AY3: =IF(OR(N(AX3)<=0,N(AW3)=0,N(AV3)=0),"",MIN(AV3,AW3/AX3)) | AZ3: =IF(OR(AY3="",N(O3)=0),"",AY3/O3-1) | BA3: =IF(OR(AZ3="",N(O3)=0),"",AZ3+AW3/O3) | BB3: =IF(OR(BA3="",N(AR3)=0),"",BA3-AR3) | BC3: =IF(OR(BA3="",N(U3)=0),"",BA3-U3) | BD3: NO PRICE; not in QOL paste - retire/rename?; group base = 0 (parent did not quote)
A4: A-C | B4: 11 | C4: ACP-A | D4: ACP | E4: ABRDN INCOME CREDIT STRATEGIES | F4: 637 | G4: PREFERRED | H4: FIXED | I4: yes | J4: Q | K4: 4 | L4: 25 | M4: 0.0525 | N4: 1.3125 | O4: 19.36 | P4: OK | Q4: 0.1 | R4: 0.095 | S4: 13.815789 | T4: -0.28637451 | U4: -0.21858009 | V4: 0 | W4: =IF(N(Q4)=0,"",Q4+IF(I4="yes",Q4*Inputs!$B$10*Inputs!$B$9,0)+V4) -> 0.095 | X4: =IF(OR(N(W4)<=0,N(N4)=0,N(L4)=0),"",MIN(L4,N4/W4)) -> 13.815789 | Y4: =IF(OR(X4="",N(O4)=0),"",X4/O4-1) -> -0.28637451 | Z4: =IF(OR(Y4="",N(O4)=0),"",Y4+N4/O4) -> -0.21858009 | AA4: =IF(OR(Z4="",N(U4)=0),"",Z4-U4) -> 0 | AB4: =IF(N(Q4)=0,"",Q4+IF(I4="yes",Q4*Inputs!$B$10*Inputs!$B$9,0)+IFERROR(INDEX(Inputs!$B$13:$B$15,MATCH(G4,Inputs!$A$13:$A$15,0)),0)+IFERROR(INDEX(Inputs!$B$18:$B$24,MATCH(H4,Inputs!$A$18:$A$24,0)),0)) -> 0.095 | AC4: =IF(OR(N(AB4)<=0,N(N4)=0,N(L4)=0),"",MIN(L4,N4/AB4)) -> 13.815789 | AD4: =IF(OR(AC4="",N(O4)=0),"",AC4/O4-1) -> -0.28637451 | AE4: =IF(OR(AD4="",N(O4)=0),"",AD4+N4/O4) -> -0.21858009 | AF4: =IF(OR(AE4="",N(Z4)=0),"",AE4-Z4) -> 0 | AG4: =IF(AND(N(M4)>0,N(L4)>0),M4*L4,N4) -> 1.3125 | AH4: =IF(OR(N(AB4)<=0,N(AG4)=0,N(L4)=0),"",MIN(L4,AG4/AB4)) -> 13.815789 | AI4: =IF(OR(AH4="",N(O4)=0),"",AH4/O4-1) -> -0.28637451 | AJ4: =IF(OR(AI4="",N(O4)=0),"",AI4+AG4/O4) -> -0.21858009 | AK4: =IF(OR(AJ4="",N(AE4)=0),"",AJ4-AE4) -> 0 | AL4: =IF(N(F4)=0,"",INDEX(Inputs!$B$28:$B$32,IFERROR(MATCH(F4,Inputs!$A$28:$A$32,1),0)+1)) -> 0.09 | AN4: =IF(N(AM4)>0,AM4,AL4) -> 0.09 | AO4: =IF(N(AN4)=0,"",AN4+IF(I4="yes",AN4*Inputs!$B$10*Inputs!$B$9,0)+IFERROR(INDEX(Inputs!$B$13:$B$15,MATCH(G4,Inputs!$A$13:$A$15,0)),0)+IFERROR(INDEX(Inputs!$B$18:$B$24,MATCH(H4,Inputs!$A$18:$A$24,0)),0)) -> 0.0855 | AP4: =IF(OR(N(AO4)<=0,N(AG4)=0,N(L4)=0),"",MIN(L4,AG4/AO4)) -> 15.350877 | AQ4: =IF(OR(AP4="",N(O4)=0),"",AP4/O4-1) -> -0.20708279 | AR4: =IF(OR(AQ4="",N(O4)=0),"",AQ4+AG4/O4) -> -0.13928837 | AS4: =IF(OR(AR4="",N(AJ4)=0),"",AR4-AJ4) -> 0.079291721 | AT4: 25 | AU4: 1.3125 | AV4: =IF(N(AT4)>0,AT4,L4) -> 25 | AW4: =IF(AND(N(M4)>0,N(AV4)>0),M4*AV4,IF(N(AU4)>0,AU4,N4)) -> 1.3125 | AX4: =IF(N(AN4)=0,"",AN4+IF(I4="yes",AN4*Inputs!$B$10*Inputs!$B$9,0)+IFERROR(INDEX(Inputs!$B$13:$B$15,MATCH(G4,Inputs!$A$13:$A$15,0)),0)+IFERROR(INDEX(Inputs!$B$18:$B$24,MATCH(H4,Inputs!$A$18:$A$24,0)),0)) -> 0.0855 | AY4: =IF(OR(N(AX4)<=0,N(AW4)=0,N(AV4)=0),"",MIN(AV4,AW4/AX4)) -> 15.350877 | AZ4: =IF(OR(AY4="",N(O4)=0),"",AY4/O4-1) -> -0.20708279 | BA4: =IF(OR(AZ4="",N(O4)=0),"",AZ4+AW4/O4) -> -0.13928837 | BB4: =IF(OR(BA4="",N(AR4)=0),"",BA4-AR4) -> 0 | BC4: =IF(OR(BA4="",N(U4)=0),"",BA4-U4) -> 0.079291721
A5: A-C | B5: 15 | C5: ACR-C | D5: ACR | E5: ACRES COMMERCIAL REALTY CORP COM NEW | F5: 104 | G5: PREFERRED | H5: FIXED | I5: yes | J5: Q | K5: 4 | L5: 25 | M5: 0.08625 | N5: 2.15625 | O5: 23.89 | P5: OK | Q5: 0.09 | R5: 0.0855 | S5: 25 | T5: 0.046462955 | U5: 0.13672039 | V5: 0 | W5: =IF(N(Q5)=0,"",Q5+IF(I5="yes",Q5*Inputs!$B$10*Inputs!$B$9,0)+V5) -> 0.0855 | X5: =IF(OR(N(W5)<=0,N(N5)=0,N(L5)=0),"",MIN(L5,N5/W5)) -> 25 | Y5: =IF(OR(X5="",N(O5)=0),"",X5/O5-1) -> 0.046462955 | Z5: =IF(OR(Y5="",N(O5)=0),"",Y5+N5/O5) -> 0.13672039 | AA5: =IF(OR(Z5="",N(U5)=0),"",Z5-U5) -> 0 | AB5: =IF(N(Q5)=0,"",Q5+IF(I5="yes",Q5*Inputs!$B$10*Inputs!$B$9,0)+IFERROR(INDEX(Inputs!$B$13:$B$15,MATCH(G5,Inputs!$A$13:$A$15,0)),0)+IFERROR(INDEX(Inputs!$B$18:$B$24,MATCH(H5,Inputs!$A$18:$A$24,0)),0)) -> 0.0855 | AC5: =IF(OR(N(AB5)<=0,N(N5)=0,N(L5)=0),"",MIN(L5,N5/AB5)) -> 25 | AD5: =IF(OR(AC5="",N(O5)=0),"",AC5/O5-1) -> 0.046462955 | AE5: =IF(OR(AD5="",N(O5)=0),"",AD5+N5/O5) -> 0.13672039 | AF5: =IF(OR(AE5="",N(Z5)=0),"",AE5-Z5) -> 0 | AG5: =IF(AND(N(M5)>0,N(L5)>0),M5*L5,N5) -> 2.15625 | AH5: =IF(OR(N(AB5)<=0,N(AG5)=0,N(L5)=0),"",MIN(L5,AG5/AB5)) -> 25 | AI5: =IF(OR(AH5="",N(O5)=0),"",AH5/O5-1) -> 0.046462955 | AJ5: =IF(OR(AI5="",N(O5)=0),"",AI5+AG5/O5) -> 0.13672039 | AK5: =IF(OR(AJ5="",N(AE5)=0),"",AJ5-AE5) -> 0 | AL5: =IF(N(F5)=0,"",INDEX(Inputs!$B$28:$B$32,IFERROR(MATCH(F5,Inputs!$A$28:$A$32,1),0)+1)) -> 0.1 | AN5: =IF(N(AM5)>0,AM5,AL5) -> 0.1 | AO5: =IF(N(AN5)=0,"",AN5+IF(I5="yes",AN5*Inputs!$B$10*Inputs!$B$9,0)+IFERROR(INDEX(Inputs!$B$13:$B$15,MATCH(G5,Inputs!$A$13:$A$15,0)),0)+IFERROR(INDEX(Inputs!$B$18:$B$24,MATCH(H5,Inputs!$A$18:$A$24,0)),0)) -> 0.095 | AP5: =IF(OR(N(AO5)<=0,N(AG5)=0,N(L5)=0),"",MIN(L5,AG5/AO5)) -> 22.697368 | AQ5: =IF(OR(AP5="",N(O5)=0),"",AP5/O5-1) -> -0.049921791 | AR5: =IF(OR(AQ5="",N(O5)=0),"",AQ5+AG5/O5) -> 0.040335639 | AS5: =IF(OR(AR5="",N(AJ5)=0),"",AR5-AJ5) -> -0.096384746 | AT5: 25 | AU5: 2.16 | AV5: =IF(N(AT5)>0,AT5,L5) -> 25 | AW5: =IF(AND(N(M5)>0,N(AV5)>0),M5*AV5,IF(N(AU5)>0,AU5,N5)) -> 2.15625 | AX5: =IF(N(AN5)=0,"",AN5+IF(I5="yes",AN5*Inputs!$B$10*Inputs!$B$9,0)+IFERROR(INDEX(Inputs!$B$13:$B$15,MATCH(G5,Inputs!$A$13:$A$15,0)),0)+IFERROR(INDEX(Inputs!$B$18:$B$24,MATCH(H5,Inputs!$A$18:$A$24,0)),0)) -> 0.095 | AY5: =IF(OR(N(AX5)<=0,N(AW5)=0,N(AV5)=0),"",MIN(AV5,AW5/AX5)) -> 22.697368 | AZ5: =IF(OR(AY5="",N(O5)=0),"",AY5/O5-1) -> -0.049921791 | BA5: =IF(OR(AZ5="",N(O5)=0),"",AZ5+AW5/O5) -> 0.040335639 | BB5: =IF(OR(BA5="",N(AR5)=0),"",BA5-AR5) -> 0 | BC5: =IF(OR(BA5="",N(U5)=0),"",BA5-U5) -> -0.096384746
A6: A-C | B6: 16 | C6: ACR-D | D6: ACR | E6: ACRES COMMERCIAL REALTY CORP COM NEW | F6: 104 | G6: PREFERRED | H6: FIXED | I6: yes | J6: Q | K6: 4 | L6: 25 | M6: 0.07875 | N6: 1.96875 | O6: 20.85 | P6: OK | Q6: 0.09 | R6: 0.0855 | S6: 23.026316 | T6: 0.10437965 | U6: 0.19880411 | V6: 0 | W6: =IF(N(Q6)=0,"",Q6+IF(I6="yes",Q6*Inputs!$B$10*Inputs!$B$9,0)+V6) -> 0.0855 | X6: =IF(OR(N(W6)<=0,N(N6)=0,N(L6)=0),"",MIN(L6,N6/W6)) -> 23.026316 | Y6: =IF(OR(X6="",N(O6)=0),"",X6/O6-1) -> 0.10437965 | Z6: =IF(OR(Y6="",N(O6)=0),"",Y6+N6/O6) -> 0.19880411 | AA6: =IF(OR(Z6="",N(U6)=0),"",Z6-U6) -> 0 | AB6: =IF(N(Q6)=0,"",Q6+IF(I6="yes",Q6*Inputs!$B$10*Inputs!$B$9,0)+IFERROR(INDEX(Inputs!$B$13:$B$15,MATCH(G6,Inputs!$A$13:$A$15,0)),0)+IFERROR(INDEX(Inputs!$B$18:$B$24,MATCH(H6,Inputs!$A$18:$A$24,0)),0)) -> 0.0855 | AC6: =IF(OR(N(AB6)<=0,N(N6)=0,N(L6)=0),"",MIN(L6,N6/AB6)) -> 23.026316 | AD6: =IF(OR(AC6="",N(O6)=0),"",AC6/O6-1) -> 0.10437965 | AE6: =IF(OR(AD6="",N(O6)=0),"",AD6+N6/O6) -> 0.19880411 | AF6: =IF(OR(AE6="",N(Z6)=0),"",AE6-Z6) -> 0 | AG6: =IF(AND(N(M6)>0,N(L6)>0),M6*L6,N6) -> 1.96875 | AH6: =IF(OR(N(AB6)<=0,N(AG6)=0,N(L6)=0),"",MIN(L6,AG6/AB6)) -> 23.026316 | AI6: =IF(OR(AH6="",N(O6)=0),"",AH6/O6-1) -> 0.10437965 | AJ6: =IF(OR(AI6="",N(O6)=0),"",AI6+AG6/O6) -> 0.19880411 | AK6: =IF(OR(AJ6="",N(AE6)=0),"",AJ6-AE6) -> 0 | AL6: =IF(N(F6)=0,"",INDEX(Inputs!$B$28:$B$32,IFERROR(MATCH(F6,Inputs!$A$28:$A$32,1),0)+1)) -> 0.1 | AN6: =IF(N(AM6)>0,AM6,AL6) -> 0.1 | AO6: =IF(N(AN6)=0,"",AN6+IF(I6="yes",AN6*Inputs!$B$10*Inputs!$B$9,0)+IFERROR(INDEX(Inputs!$B$13:$B$15,MATCH(G6,Inputs!$A$13:$A$15,0)),0)+IFERROR(INDEX(Inputs!$B$18:$B$24,MATCH(H6,Inputs!$A$18:$A$24,0)),0)) -> 0.095 | AP6: =IF(OR(N(AO6)<=0,N(AG6)=0,N(L6)=0),"",MIN(L6,AG6/AO6)) -> 20.723684 | AQ6: =IF(OR(AP6="",N(O6)=0),"",AP6/O6-1) -> -0.0060583112 | AR6: =IF(OR(AQ6="",N(O6)=0),"",AQ6+AG6/O6) -> 0.088366149 | AS6: =IF(OR(AR6="",N(AJ6)=0),"",AR6-AJ6) -> -0.11043797 | AT6: 25 | AU6: 1.96875 | AV6: =IF(N(AT6)>0,AT6,L6) -> 25 | AW6: =IF(AND(N(M6)>0,N(AV6)>0),M6*AV6,IF(N(AU6)>0,AU6,N6)) -> 1.96875 | AX6: =IF(N(AN6)=0,"",AN6+IF(I6="yes",AN6*Inputs!$B$10*Inputs!$B$9,0)+IFERROR(INDEX(Inputs!$B$13:$B$15,MATCH(G6,Inputs!$A$13:$A$15,0)),0)+IFERROR(INDEX(Inputs!$B$18:$B$24,MATCH(H6,Inputs!$A$18:$A$24,0)),0)) -> 0.095 | AY6: =IF(OR(N(AX6)<=0,N(AW6)=0,N(AV6)=0),"",MIN(AV6,AW6/AX6)) -> 20.723684 | AZ6: =IF(OR(AY6="",N(O6)=0),"",AY6/O6-1) -> -0.0060583112 | BA6: =IF(OR(AZ6="",N(O6)=0),"",AZ6+AW6/O6) -> 0.088366149 | BB6: =IF(OR(BA6="",N(AR6)=0),"",BA6-AR6) -> 0 | BC6: =IF(OR(BA6="",N(U6)=0),"",BA6-U6) -> -0.11043797
A7: A-C | B7: 19 | C7: ABR-D | D7: ABR | E7: ARBOR REALTY TRUST INC | F7: 966 | G7: PREFERRED | H7: FIXED | I7: no | J7: Q | K7: 4 | L7: 25 | M7: 0.06375 | N7: 1.59375 | O7: 15.94 | P7: OK | Q7: 0.1 | R7: 0.1 | S7: 15.9375 | T7: -0.00015683814 | U7: 0.099827478 | V7: 0 | W7: =IF(N(Q7)=0,"",Q7+IF(I7="yes",Q7*Inputs!$B$10*Inputs!$B$9,0)+V7) -> 0.1 | X7: =IF(OR(N(W7)<=0,N(N7)=0,N(L7)=0),"",MIN(L7,N7/W7)) -> 15.9375 | Y7: =IF(OR(X7="",N(O7)=0),"",X7/O7-1) -> -0.00015683814 | Z7: =IF(OR(Y7="",N(O7)=0),"",Y7+N7/O7) -> 0.099827478 | AA7: =IF(OR(Z7="",N(U7)=0),"",Z7-U7) -> 0 | AB7: =IF(N(Q7)=0,"",Q7+IF(I7="yes",Q7*Inputs!$B$10*Inputs!$B$9,0)+IFERROR(INDEX(Inputs!$B$13:$B$15,MATCH(G7,Inputs!$A$13:$A$15,0)),0)+IFERROR(INDEX(Inputs!$B$18:$B$24,MATCH(H7,Inputs!$A$18:$A$24,0)),0)) -> 0.1 | AC7: =IF(OR(N(AB7)<=0,N(N7)=0,N(L7)=0),"",MIN(L7,N7/AB7)) -> 15.9375 | AD7: =IF(OR(AC7="",N(O7)=0),"",AC7/O7-1) -> -0.00015683814 | AE7: =IF(OR(AD7="",N(O7)=0),"",AD7+N7/O7) -> 0.099827478 | AF7: =IF(OR(AE7="",N(Z7)=0),"",AE7-Z7) -> 0 | AG7: =IF(AND(N(M7)>0,N(L7)>0),M7*L7,N7) -> 1.59375 | AH7: =IF(OR(N(AB7)<=0,N(AG7)=0,N(L7)=0),"",MIN(L7,AG7/AB7)) -> 15.9375 | AI7: =IF(OR(AH7="",N(O7)=0),"",AH7/O7-1) -> -0.00015683814 | AJ7: =IF(OR(AI7="",N(O7)=0),"",AI7+AG7/O7) -> 0.099827478 | AK7: =IF(OR(AJ7="",N(AE7)=0),"",AJ7-AE7) -> 0 | AL7: =IF(N(F7)=0,"",INDEX(Inputs!$B$28:$B$32,IFERROR(MATCH(F7,Inputs!$A$28:$A$32,1),0)+1)) -> 0.09 | AN7: =IF(N(AM7)>0,AM7,AL7) -> 0.09 | AO7: =IF(N(AN7)=0,"",AN7+IF(I7="yes",AN7*Inputs!$B$10*Inputs!$B$9,0)+IFERROR(INDEX(Inputs!$B$13:$B$15,MATCH(G7,Inputs!$A$13:$A$15,0)),0)+IFERROR(INDEX(Inputs!$B$18:$B$24,MATCH(H7,Inputs!$A$18:$A$24,0)),0)) -> 0.09 | AP7: =IF(OR(N(AO7)<=0,N(AG7)=0,N(L7)=0),"",MIN(L7,AG7/AO7)) -> 17.708333 | AQ7: =IF(OR(AP7="",N(O7)=0),"",AP7/O7-1) -> 0.11093685 | AR7: =IF(OR(AQ7="",N(O7)=0),"",AQ7+AG7/O7) -> 0.21092116 | AS7: =IF(OR(AR7="",N(AJ7)=0),"",AR7-AJ7) -> 0.11109368 | AT7: 25 | AU7: 1.59375 | AV7: =IF(N(AT7)>0,AT7,L7) -> 25 | AW7: =IF(AND(N(M7)>0,N(AV7)>0),M7*AV7,IF(N(AU7)>0,AU7,N7)) -> 1.59375 | AX7: =IF(N(AN7)=0,"",AN7+IF(I7="yes",AN7*Inputs!$B$10*Inputs!$B$9,0)+IFERROR(INDEX(Inputs!$B$13:$B$15,MATCH(G7,Inputs!$A$13:$A$15,0)),0)+IFERROR(INDEX(Inputs!$B$18:$B$24,MATCH(H7,Inputs!$A$18:$A$24,0)),0)) -> 0.09 | AY7: =IF(OR(N(AX7)<=0,N(AW7)=0,N(AV7)=0),"",MIN(AV7,AW7/AX7)) -> 17.708333 | AZ7: =IF(OR(AY7="",N(O7)=0),"",AY7/O7-1) -> 0.11093685 | BA7: =IF(OR(AZ7="",N(O7)=0),"",AZ7+AW7/O7) -> 0.21092116 | BB7: =IF(OR(BA7="",N(AR7)=0),"",BA7-AR7) -> 0 | BC7: =IF(OR(BA7="",N(U7)=0),"",BA7-U7) -> 0.11109368
A8: A-C | B8: 20 | C8: ABR-E | D8: ABR | E8: ARBOR REALTY TRUST INC | F8: 966 | G8: PREFERRED | H8: FIXED | I8: no | J8: Q | K8: 4 | L8: 25 | M8: 0.0625 | N8: 1.5625 | O8: 15.75 | P8: OK | Q8: 0.1 | R8: 0.1 | S8: 15.625 | T8: -0.0079365079 | U8: 0.091269841 | V8: 0 | W8: =IF(N(Q8)=0,"",Q8+IF(I8="yes",Q8*Inputs!$B$10*Inputs!$B$9,0)+V8) -> 0.1 | X8: =IF(OR(N(W8)<=0,N(N8)=0,N(L8)=0),"",MIN(L8,N8/W8)) -> 15.625 | Y8: =IF(OR(X8="",N(O8)=0),"",X8/O8-1) -> -0.0079365079 | Z8: =IF(OR(Y8="",N(O8)=0),"",Y8+N8/O8) -> 0.091269841 | AA8: =IF(OR(Z8="",N(U8)=0),"",Z8-U8) -> 0 | AB8: =IF(N(Q8)=0,"",Q8+IF(I8="yes",Q8*Inputs!$B$10*Inputs!$B$9,0)+IFERROR(INDEX(Inputs!$B$13:$B$15,MATCH(G8,Inputs!$A$13:$A$15,0)),0)+IFERROR(INDEX(Inputs!$B$18:$B$24,MATCH(H8,Inputs!$A$18:$A$24,0)),0)) -> 0.1 | AC8: =IF(OR(N(AB8)<=0,N(N8)=0,N(L8)=0),"",MIN(L8,N8/AB8)) -> 15.625 | AD8: =IF(OR(AC8="",N(O8)=0),"",AC8/O8-1) -> -0.0079365079 | AE8: =IF(OR(AD8="",N(O8)=0),"",AD8+N8/O8) -> 0.091269841 | AF8: =IF(OR(AE8="",N(Z8)=0),"",AE8-Z8) -> 0 | AG8: =IF(AND(N(M8)>0,N(L8)>0),M8*L8,N8) -> 1.5625 | AH8: =IF(OR(N(AB8)<=0,N(AG8)=0,N(L8)=0),"",MIN(L8,AG8/AB8)) -> 15.625 | AI8: =IF(OR(AH8="",N(O8)=0),"",AH8/O8-1) -> -0.0079365079 | AJ8: =IF(OR(AI8="",N(O8)=0),"",AI8+AG8/O8) -> 0.091269841 | AK8: =IF(OR(AJ8="",N(AE8)=0),"",AJ8-AE8) -> 0 | AL8: =IF(N(F8)=0,"",INDEX(Inputs!$B$28:$B$32,IFERROR(MATCH(F8,Inputs!$A$28:$A$32,1),0)+1)) -> 0.09 | AN8: =IF(N(AM8)>0,AM8,AL8) -> 0.09 | AO8: =IF(N(AN8)=0,"",AN8+IF(I8="yes",AN8*Inputs!$B$10*Inputs!$B$9,0)+IFERROR(INDEX(Inputs!$B$13:$B$15,MATCH(G8,Inputs!$A$13:$A$15,0)),0)+IFERROR(INDEX(Inputs!$B$18:$B$24,MATCH(H8,Inputs!$A$18:$A$24,0)),0)) -> 0.09 | AP8: =IF(OR(N(AO8)<=0,N(AG8)=0,N(L8)=0),"",MIN(L8,AG8/AO8)) -> 17.361111 | AQ8: =IF(OR(AP8="",N(O8)=0),"",AP8/O8-1) -> 0.10229277 | AR8: =IF(OR(AQ8="",N(O8)=0),"",AQ8+AG8/O8) -> 0.20149912 | AS8: =IF(OR(AR8="",N(AJ8)=0),"",AR8-AJ8) -> 0.11022928 | AT8: 25 | AU8: 1.5625 | AV8: =IF(N(AT8)>0,AT8,L8) -> 25 | AW8: =IF(AND(N(M8)>0,N(AV8)>0),M8*AV8,IF(N(AU8)>0,AU8,N8)) -> 1.5625 | AX8: =IF(N(AN8)=0,"",AN8+IF(I8="yes",AN8*Inputs!$B$10*Inputs!$B$9,0)+IFERROR(INDEX(Inputs!$B$13:$B$15,MATCH(G8,Inputs!$A$13:$A$15,0)),0)+IFERROR(INDEX(Inputs!$B$18:$B$24,MATCH(H8,Inputs!$A$18:$A$24,0)),0)) -> 0.09 | AY8: =IF(OR(N(AX8)<=0,N(AW8)=0,N(AV8)=0),"",MIN(AV8,AW8/AX8)) -> 17.361111 | AZ8: =IF(OR(AY8="",N(O8)=0),"",AY8/O8-1) -> 0.10229277 | BA8: =IF(OR(AZ8="",N(O8)=0),"",AZ8+AW8/O8) -> 0.20149912 | BB8: =IF(OR(BA8="",N(AR8)=0),"",BA8-AR8) -> 0 | BC8: =IF(OR(BA8="",N(U8)=0),"",BA8-U8) -> 0.11022928
A9: A-C | B9: 21 | C9: ABR-F | D9: ABR | E9: ARBOR REALTY TRUST INC | F9: 966 | G9: PREFERRED | H9: FIXED | I9: no | J9: Q | K9: 4 | L9: 25 | M9: 0.0625 | N9: 1.5625 | O9: 22.34 | P9: OK | Q9: 0.1 | R9: 0.1 | S9: 15.625 | T9: -0.30058192 | U9: -0.23064011 | V9: 0 | W9: =IF(N(Q9)=0,"",Q9+IF(I9="yes",Q9*Inputs!$B$10*Inputs!$B$9,0)+V9) -> 0.1 | X9: =IF(OR(N(W9)<=0,N(N9)=0,N(L9)=0),"",MIN(L9,N9/W9)) -> 15.625 | Y9: =IF(OR(X9="",N(O9)=0),"",X9/O9-1) -> -0.30058192 | Z9: =IF(OR(Y9="",N(O9)=0),"",Y9+N9/O9) -> -0.23064011 | AA9: =IF(OR(Z9="",N(U9)=0),"",Z9-U9) -> 0 | AB9: =IF(N(Q9)=0,"",Q9+IF(I9="yes",Q9*Inputs!$B$10*Inputs!$B$9,0)+IFERROR(INDEX(Inputs!$B$13:$B$15,MATCH(G9,Inputs!$A$13:$A$15,0)),0)+IFERROR(INDEX(Inputs!$B$18:$B$24,MATCH(H9,Inputs!$A$18:$A$24,0)),0)) -> 0.1 | AC9: =IF(OR(N(AB9)<=0,N(N9)=0,N(L9)=0),"",MIN(L9,N9/AB9)) -> 15.625 | AD9: =IF(OR(AC9="",N(O9)=0),"",AC9/O9-1) -> -0.30058192 | AE9: =IF(OR(AD9="",N(O9)=0),"",AD9+N9/O9) -> -0.23064011 | AF9: =IF(OR(AE9="",N(Z9)=0),"",AE9-Z9) -> 0 | AG9: =IF(AND(N(M9)>0,N(L9)>0),M9*L9,N9) -> 1.5625 | AH9: =IF(OR(N(AB9)<=0,N(AG9)=0,N(L9)=0),"",MIN(L9,AG9/AB9)) -> 15.625 | AI9: =IF(OR(AH9="",N(O9)=0),"",AH9/O9-1) -> -0.30058192 | AJ9: =IF(OR(AI9="",N(O9)=0),"",AI9+AG9/O9) -> -0.23064011 | AK9: =IF(OR(AJ9="",N(AE9)=0),"",AJ9-AE9) -> 0 | AL9: =IF(N(F9)=0,"",INDEX(Inputs!$B$28:$B$32,IFERROR(MATCH(F9,Inputs!$A$28:$A$32,1),0)+1)) -> 0.09 | AN9: =IF(N(AM9)>0,AM9,AL9) -> 0.09 | AO9: =IF(N(AN9)=0,"",AN9+IF(I9="yes",AN9*Inputs!$B$10*Inputs!$B$9,0)+IFERROR(INDEX(Inputs!$B$13:$B$15,MATCH(G9,Inputs!$A$13:$A$15,0)),0)+IFERROR(INDEX(Inputs!$B$18:$B$24,MATCH(H9,Inputs!$A$18:$A$24,0)),0)) -> 0.09 | AP9: =IF(OR(N(AO9)<=0,N(AG9)=0,N(L9)=0),"",MIN(L9,AG9/AO9)) -> 17.361111 | AQ9: =IF(OR(AP9="",N(O9)=0),"",AP9/O9-1) -> -0.2228688 | AR9: =IF(OR(AQ9="",N(O9)=0),"",AQ9+AG9/O9) -> -0.15292699 | AS9: =IF(OR(AR9="",N(AJ9)=0),"",AR9-AJ9) -> 0.07771312 | AT9: 25 | AU9: 1.5625 | AV9: =IF(N(AT9)>0,AT9,L9) -> 25 | AW9: =IF(AND(N(M9)>0,N(AV9)>0),M9*AV9,IF(N(AU9)>0,AU9,N9)) -> 1.5625 | AX9: =IF(N(AN9)=0,"",AN9+IF(I9="yes",AN9*Inputs!$B$10*Inputs!$B$9,0)+IFERROR(INDEX(Inputs!$B$13:$B$15,MATCH(G9,Inputs!$A$13:$A$15,0)),0)+IFERROR(INDEX(Inputs!$B$18:$B$24,MATCH(H9,Inputs!$A$18:$A$24,0)),0)) -> 0.09 | AY9: =IF(OR(N(AX9)<=0,N(AW9)=0,N(AV9)=0),"",MIN(AV9,AW9/AX9)) -> 17.361111 | AZ9: =IF(OR(AY9="",N(O9)=0),"",AY9/O9-1) -> -0.2228688 | BA9: =IF(OR(AZ9="",N(O9)=0),"",AZ9+AW9/O9) -> -0.15292699 | BB9: =IF(OR(BA9="",N(AR9)=0),"",BA9-AR9) -> 0 | BC9: =IF(OR(BA9="",N(U9)=0),"",BA9-U9) -> 0.07771312
A10: A-C | B10: 24 | C10: ACGLN | D10: ACGL | E10: ARCH CAP GROUP LTD | F10: 33900 | G10: PREFERRED | H10: FIXED | I10: yes | J10: Q | K10: 4 | L10: 25 | M10: 0.0455 | N10: 1.1375 | O10: 16.01 | P10: OK | Q10: 0.08 | R10: 0.076 | S10: 14.967105 | T10: -0.065140208 | U10: 0.0059091357 | V10: 0 | W10: =IF(N(Q10)=0,"",Q10+IF(I10="yes",Q10*Inputs!$B$10*Inputs!$B$9,0)+V10) -> 0.076 | X10: =IF(OR(N(W10)<=0,N(N10)=0,N(L10)=0),"",MIN(L10,N10/W10)) -> 14.967105 | Y10: =IF(OR(X10="",N(O10)=0),"",X10/O10-1) -> -0.065140208 | Z10: =IF(OR(Y10="",N(O10)=0),"",Y10+N10/O10) -> 0.0059091357 | AA10: =IF(OR(Z10="",N(U10)=0),"",Z10-U10) -> 0 | AB10: =IF(N(Q10)=0,"",Q10+IF(I10="yes",Q10*Inputs!$B$10*Inputs!$B$9,0)+IFERROR(INDEX(Inputs!$B$13:$B$15,MATCH(G10,Inputs!$A$13:$A$15,0)),0)+IFERROR(INDEX(Inputs!$B$18:$B$24,MATCH(H10,Inputs!$A$18:$A$24,0)),0)) -> 0.076 | AC10: =IF(OR(N(AB10)<=0,N(N10)=0,N(L10)=0),"",MIN(L10,N10/AB10)) -> 14.967105 | AD10: =IF(OR(AC10="",N(O10)=0),"",AC10/O10-1) -> -0.065140208 | AE10: =IF(OR(AD10="",N(O10)=0),"",AD10+N10/O10) -> 0.0059091357 | AF10: =IF(OR(AE10="",N(Z10)=0),"",AE10-Z10) -> 0 | AG10: =IF(AND(N(M10)>0,N(L10)>0),M10*L10,N10) -> 1.1375 | AH10: =IF(OR(N(AB10)<=0,N(AG10)=0,N(L10)=0),"",MIN(L10,AG10/AB10)) -> 14.967105 | AI10: =IF(OR(AH10="",N(O10)=0),"",AH10/O10-1) -> -0.065140208 | AJ10: =IF(OR(AI10="",N(O10)=0),"",AI10+AG10/O10) -> 0.0059091357 | AK10: =IF(OR(AJ10="",N(AE10)=0),"",AJ10-AE10) -> 0 | AL10: =IF(N(F10)=0,"",INDEX(Inputs!$B$28:$B$32,IFERROR(MATCH(F10,Inputs!$A$28:$A$32,1),0)+1)) -> 0.075 | AN10: =IF(N(AM10)>0,AM10,AL10) -> 0.075 | AO10: =IF(N(AN10)=0,"",AN10+IF(I10="yes",AN10*Inputs!$B$10*Inputs!$B$9,0)+IFERROR(INDEX(Inputs!$B$13:$B$15,MATCH(G10,Inputs!$A$13:$A$15,0)),0)+IFERROR(INDEX(Inputs!$B$18:$B$24,MATCH(H10,Inputs!$A$18:$A$24,0)),0)) -> 0.07125 | AP10: =IF(OR(N(AO10)<=0,N(AG10)=0,N(L10)=0),"",MIN(L10,AG10/AO10)) -> 15.964912 | AQ10: =IF(OR(AP10="",N(O10)=0),"",AP10/O10-1) -> -0.0028162223 | AR10: =IF(OR(AQ10="",N(O10)=0),"",AQ10+AG10/O10) -> 0.068233122 | AS10: =IF(OR(AR10="",N(AJ10)=0),"",AR10-AJ10) -> 0.062323986 | AT10: 25 | AU10: 1.1375 | AV10: =IF(N(AT10)>0,AT10,L10) -> 25 | AW10: =IF(AND(N(M10)>0,N(AV10)>0),M10*AV10,IF(N(AU10)>0,AU10,N10)) -> 1.1375 | AX10: =IF(N(AN10)=0,"",AN10+IF(I10="yes",AN10*Inputs!$B$10*Inputs!$B$9,0)+IFERROR(INDEX(Inputs!$B$13:$B$15,MATCH(G10,Inputs!$A$13:$A$15,0)),0)+IFERROR(INDEX(Inputs!$B$18:$B$24,MATCH(H10,Inputs!$A$18:$A$24,0)),0)) -> 0.07125 | AY10: =IF(OR(N(AX10)<=0,N(AW10)=0,N(AV10)=0),"",MIN(AV10,AW10/AX10)) -> 15.964912 | AZ10: =IF(OR(AY10="",N(O10)=0),"",AY10/O10-1) -> -0.0028162223 | BA10: =IF(OR(AZ10="",N(O10)=0),"",AZ10+AW10/O10) -> 0.068233122 | BB10: =IF(OR(BA10="",N(AR10)=0),"",BA10-AR10) -> 0 | BC10: =IF(OR(BA10="",N(U10)=0),"",BA10-U10) -> 0.062323986
A11: A-C | B11: 25 | C11: ACGLO | D11: ACGL | E11: ARCH CAP GROUP LTD | F11: 33900 | G11: PREFERRED | H11: FIXED | I11: yes | J11: Q | K11: 4 | L11: 25 | M11: 0.0545 | N11: 1.3625 | O11: 18.96 | P11: OK | Q11: 0.08 | R11: 0.076 | S11: 17.927632 | T11: -0.054449811 | U11: 0.017412003 | V11: 0 | W11: =IF(N(Q11)=0,"",Q11+IF(I11="yes",Q11*Inputs!$B$10*Inputs!$B$9,0)+V11) -> 0.076 | X11: =IF(OR(N(W11)<=0,N(N11)=0,N(L11)=0),"",MIN(L11,N11/W11)) -> 17.927632 | Y11: =IF(OR(X11="",N(O11)=0),"",X11/O11-1) -> -0.054449811 | Z11: =IF(OR(Y11="",N(O11)=0),"",Y11+N11/O11) -> 0.017412003 | AA11: =IF(OR(Z11="",N(U11)=0),"",Z11-U11) -> 0 | AB11: =IF(N(Q11)=0,"",Q11+IF(I11="yes",Q11*Inputs!$B$10*Inputs!$B$9,0)+IFERROR(INDEX(Inputs!$B$13:$B$15,MATCH(G11,Inputs!$A$13:$A$15,0)),0)+IFERROR(INDEX(Inputs!$B$18:$B$24,MATCH(H11,Inputs!$A$18:$A$24,0)),0)) -> 0.076 | AC11: =IF(OR(N(AB11)<=0,N(N11)=0,N(L11)=0),"",MIN(L11,N11/AB11)) -> 17.927632 | AD11: =IF(OR(AC11="",N(O11)=0),"",AC11/O11-1) -> -0.054449811 | AE11: =IF(OR(AD11="",N(O11)=0),"",AD11+N11/O11) -> 0.017412003 | AF11: =IF(OR(AE11="",N(Z11)=0),"",AE11-Z11) -> 0 | AG11: =IF(AND(N(M11)>0,N(L11)>0),M11*L11,N11) -> 1.3625 | AH11: =IF(OR(N(AB11)<=0,N(AG11)=0,N(L11)=0),"",MIN(L11,AG11/AB11)) -> 17.927632 | AI11: =IF(OR(AH11="",N(O11)=0),"",AH11/O11-1) -> -0.054449811 | AJ11: =IF(OR(AI11="",N(O11)=0),"",AI11+AG11/O11) -> 0.017412003 | AK11: =IF(OR(AJ11="",N(AE11)=0),"",AJ11-AE11) -> 0 | AL11: =IF(N(F11)=0,"",INDEX(Inputs!$B$28:$B$32,IFERROR(MATCH(F11,Inputs!$A$28:$A$32,1),0)+1)) -> 0.075 | AN11: =IF(N(AM11)>0,AM11,AL11) -> 0.075 | AO11: =IF(N(AN11)=0,"",AN11+IF(I11="yes",AN11*Inputs!$B$10*Inputs!$B$9,0)+IFERROR(INDEX(Inputs!$B$13:$B$15,MATCH(G11,Inputs!$A$13:$A$15,0)),0)+IFERROR(INDEX(Inputs!$B$18:$B$24,MATCH(H11,Inputs!$A$18:$A$24,0)),0)) -> 0.07125 | AP11: =IF(OR(N(AO11)<=0,N(AG11)=0,N(L11)=0),"",MIN(L11,AG11/AO11)) -> 19.122807 | AQ11: =IF(OR(AP11="",N(O11)=0),"",AP11/O11-1) -> 0.008586868 | AR11: =IF(OR(AQ11="",N(O11)=0),"",AQ11+AG11/O11) -> 0.080448682 | AS11: =IF(OR(AR11="",N(AJ11)=0),"",AR11-AJ11) -> 0.063036679 | AT11: 25 | AU11: 1.36 | AV11: =IF(N(AT11)>0,AT11,L11) -> 25 | AW11: =IF(AND(N(M11)>0,N(AV11)>0),M11*AV11,IF(N(AU11)>0,AU11,N11)) -> 1.3625 | AX11: =IF(N(AN11)=0,"",AN11+IF(I11="yes",AN11*Inputs!$B$10*Inputs!$B$9,0)+IFERROR(INDEX(Inputs!$B$13:$B$15,MATCH(G11,Inputs!$A$13:$A$15,0)),0)+IFERROR(INDEX(Inputs!$B$18:$B$24,MATCH(H11,Inputs!$A$18:$A$24,0)),0)) -> 0.07125 | AY11: =IF(OR(N(AX11)<=0,N(AW11)=0,N(AV11)=0),"",MIN(AV11,AW11/AX11)) -> 19.122807 | AZ11: =IF(OR(AY11="",N(O11)=0),"",AY11/O11-1) -> 0.008586868 | BA11: =IF(OR(AZ11="",N(O11)=0),"",AZ11+AW11/O11) -> 0.080448682 | BB11: =IF(OR(BA11="",N(AR11)=0),"",BA11-AR11) -> 0 | BC11: =IF(OR(BA11="",N(U11)=0),"",BA11-U11) -> 0.063036679
A12: A-C | B12: 28 | C12: ADC-A | D12: ADC | E12: AGREE RLTY CORP | F12: 9300 | G12: PREFERRED | H12: FIXED | I12: no | J12: M | K12: 12 | L12: 25 | M12: 0.0425 | N12: 1.0625 | O12: 16.86 | P12: OK | Q12: 0.08 | R12: 0.08 | S12: 13.28125 | T12: -0.21226275 | U12: -0.14924377 | V12: 0 | W12: =IF(N(Q12)=0,"",Q12+IF(I12="yes",Q12*Inputs!$B$10*Inputs!$B$9,0)+V12) -> 0.08 | X12: =IF(OR(N(W12)<=0,N(N12)=0,N(L12)=0),"",MIN(L12,N12/W12)) -> 13.28125 | Y12: =IF(OR(X12="",N(O12)=0),"",X12/O12-1) -> -0.21226275 | Z12: =IF(OR(Y12="",N(O12)=0),"",Y12+N12/O12) -> -0.14924377 | AA12: =IF(OR(Z12="",N(U12)=0),"",Z12-U12) -> 0 | AB12: =IF(N(Q12)=0,"",Q12+IF(I12="yes",Q12*Inputs!$B$10*Inputs!$B$9,0)+IFERROR(INDEX(Inputs!$B$13:$B$15,MATCH(G12,Inputs!$A$13:$A$15,0)),0)+IFERROR(INDEX(Inputs!$B$18:$B$24,MATCH(H12,Inputs!$A$18:$A$24,0)),0)) -> 0.08 | AC12: =IF(OR(N(AB12)<=0,N(N12)=0,N(L12)=0),"",MIN(L12,N12/AB12)) -> 13.28125 | AD12: =IF(OR(AC12="",N(O12)=0),"",AC12/O12-1) -> -0.21226275 | AE12: =IF(OR(AD12="",N(O12)=0),"",AD12+N12/O12) -> -0.14924377 | AF12: =IF(OR(AE12="",N(Z12)=0),"",AE12-Z12) -> 0 | AG12: =IF(AND(N(M12)>0,N(L12)>0),M12*L12,N12) -> 1.0625 | AH12: =IF(OR(N(AB12)<=0,N(AG12)=0,N(L12)=0),"",MIN(L12,AG12/AB12)) -> 13.28125 | AI12: =IF(OR(AH12="",N(O12)=0),"",AH12/O12-1) -> -0.21226275 | AJ12: =IF(OR(AI12="",N(O12)=0),"",AI12+AG12/O12) -> -0.14924377 | AK12: =IF(OR(AJ12="",N(AE12)=0),"",AJ12-AE12) -> 0 | AL12: =IF(N(F12)=0,"",INDEX(Inputs!$B$28:$B$32,IFERROR(MATCH(F12,Inputs!$A$28:$A$32,1),0)+1)) -> 0.08 | AN12: =IF(N(AM12)>0,AM12,AL12) -> 0.08 | AO12: =IF(N(AN12)=0,"",AN12+IF(I12="yes",AN12*Inputs!$B$10*Inputs!$B$9,0)+IFERROR(INDEX(Inputs!$B$13:$B$15,MATCH(G12,Inputs!$A$13:$A$15,0)),0)+IFERROR(INDEX(Inputs!$B$18:$B$24,MATCH(H12,Inputs!$A$18:$A$24,0)),0)) -> 0.08 | AP12: =IF(OR(N(AO12)<=0,N(AG12)=0,N(L12)=0),"",MIN(L12,AG12/AO12)) -> 13.28125 | AQ12: =IF(OR(AP12="",N(O12)=0),"",AP12/O12-1) -> -0.21226275 | AR12: =IF(OR(AQ12="",N(O12)=0),"",AQ12+AG12/O12) -> -0.14924377 | AS12: =IF(OR(AR12="",N(AJ12)=0),"",AR12-AJ12) -> 0 | AT12: 25 | AU12: 1.0625 | AV12: =IF(N(AT12)>0,AT12,L12) -> 25 | AW12: =IF(AND(N(M12)>0,N(AV12)>0),M12*AV12,IF(N(AU12)>0,AU12,N12)) -> 1.0625 | AX12: =IF(N(AN12)=0,"",AN12+IF(I12="yes",AN12*Inputs!$B$10*Inputs!$B$9,0)+IFERROR(INDEX(Inputs!$B$13:$B$15,MATCH(G12,Inputs!$A$13:$A$15,0)),0)+IFERROR(INDEX(Inputs!$B$18:$B$24,MATCH(H12,Inputs!$A$18:$A$24,0)),0)) -> 0.08 | AY12: =IF(OR(N(AX12)<=0,N(AW12)=0,N(AV12)=0),"",MIN(AV12,AW12/AX12)) -> 13.28125 | AZ12: =IF(OR(AY12="",N(O12)=0),"",AY12/O12-1) -> -0.21226275 | BA12: =IF(OR(AZ12="",N(O12)=0),"",AZ12+AW12/O12) -> -0.14924377 | BB12: =IF(OR(BA12="",N(AR12)=0),"",BA12-AR12) -> 0 | BC12: =IF(OR(BA12="",N(U12)=0),"",BA12-U12) -> 0
A13: A-C | B13: 32 | C13: AILIH | D13: AEE | E13: AMEREN CORP | F13: 30100 | G13: PREFERRED | H13: FIXED | I13: yes | J13: Q | K13: 4 | L13: 50 | M13: 0.0408 | N13: 2.04 | O13: 66 | P13: OK | Q13: 0.08 | R13: 0.076 | S13: 26.842105 | T13: -0.59330144 | U13: -0.56239234 | V13: 0 | W13: =IF(N(Q13)=0,"",Q13+IF(I13="yes",Q13*Inputs!$B$10*Inputs!$B$9,0)+V13) -> 0.076 | X13: =IF(OR(N(W13)<=0,N(N13)=0,N(L13)=0),"",MIN(L13,N13/W13)) -> 26.842105 | Y13: =IF(OR(X13="",N(O13)=0),"",X13/O13-1) -> -0.59330144 | Z13: =IF(OR(Y13="",N(O13)=0),"",Y13+N13/O13) -> -0.56239234 | AA13: =IF(OR(Z13="",N(U13)=0),"",Z13-U13) -> 0 | AB13: =IF(N(Q13)=0,"",Q13+IF(I13="yes",Q13*Inputs!$B$10*Inputs!$B$9,0)+IFERROR(INDEX(Inputs!$B$13:$B$15,MATCH(G13,Inputs!$A$13:$A$15,0)),0)+IFERROR(INDEX(Inputs!$B$18:$B$24,MATCH(H13,Inputs!$A$18:$A$24,0)),0)) -> 0.076 | AC13: =IF(OR(N(AB13)<=0,N(N13)=0,N(L13)=0),"",MIN(L13,N13/AB13)) -> 26.842105 | AD13: =IF(OR(AC13="",N(O13)=0),"",AC13/O13-1) -> -0.59330144 | AE13: =IF(OR(AD13="",N(O13)=0),"",AD13+N13/O13) -> -0.56239234 | AF13: =IF(OR(AE13="",N(Z13)=0),"",AE13-Z13) -> 0 | AG13: =IF(AND(N(M13)>0,N(L13)>0),M13*L13,N13) -> 2.04 | AH13: =IF(OR(N(AB13)<=0,N(AG13)=0,N(L13)=0),"",MIN(L13,AG13/AB13)) -> 26.842105 | AI13: =IF(OR(AH13="",N(O13)=0),"",AH13/O13-1) -> -0.59330144 | AJ13: =IF(OR(AI13="",N(O13)=0),"",AI13+AG13/O13) -> -0.56239234 | AK13: =IF(OR(AJ13="",N(AE13)=0),"",AJ13-AE13) -> 0 | AL13: =IF(N(F13)=0,"",INDEX(Inputs!$B$28:$B$32,IFERROR(MATCH(F13,Inputs!$A$28:$A$32,1),0)+1)) -> 0.075 | AN13: =IF(N(AM13)>0,AM13,AL13) -> 0.075 | AO13: =IF(N(AN13)=0,"",AN13+IF(I13="yes",AN13*Inputs!$B$10*Inputs!$B$9,0)+IFERROR(INDEX(Inputs!$B$13:$B$15,MATCH(G13,Inputs!$A$13:$A$15,0)),0)+IFERROR(INDEX(Inputs!$B$18:$B$24,MATCH(H13,Inputs!$A$18:$A$24,0)),0)) -> 0.07125 | AP13: =IF(OR(N(AO13)<=0,N(AG13)=0,N(L13)=0),"",MIN(L13,AG13/AO13)) -> 28.631579 | AQ13: =IF(OR(AP13="",N(O13)=0),"",AP13/O13-1) -> -0.5661882 | AR13: =IF(OR(AQ13="",N(O13)=0),"",AQ13+AG13/O13) -> -0.53527911 | AS13: =IF(OR(AR13="",N(AJ13)=0),"",AR13-AJ13) -> 0.027113238 | AT13: 100 | AU13: 4.08 | AV13: =IF(N(AT13)>0,AT13,L13) -> 100 | AW13: =IF(AND(N(M13)>0,N(AV13)>0),M13*AV13,IF(N(AU13)>0,AU13,N13)) -> 4.08 | AX13: =IF(N(AN13)=0,"",AN13+IF(I13="yes",AN13*Inputs!$B$10*Inputs!$B$9,0)+IFERROR(INDEX(Inputs!$B$13:$B$15,MATCH(G13,Inputs!$A$13:$A$15,0)),0)+IFERROR(INDEX(Inputs!$B$18:$B$24,MATCH(H13,Inputs!$A$18:$A$24,0)),0)) -> 0.07125 | AY13: =IF(OR(N(AX13)<=0,N(AW13)=0,N(AV13)=0),"",MIN(AV13,AW13/AX13)) -> 57.263158 | AZ13: =IF(OR(AY13="",N(O13)=0),"",AY13/O13-1) -> -0.1323764 | BA13: =IF(OR(AZ13="",N(O13)=0),"",AZ13+AW13/O13) -> -0.070558214 | BB13: =IF(OR(BA13="",N(AR13)=0),"",BA13-AR13) -> 0.46472089 | BC13: =IF(OR(BA13="",N(U13)=0),"",BA13-U13) -> 0.49183413 | BD13: PAR MISMATCH
A14: A-C | B14: 33 | C14: AILIM | D14: AEE | E14: AMEREN CORP | F14: 30100 | G14: PREFERRED | H14: FIXED | I14: yes | J14: Q | K14: 4 | L14: 50 | M14: 0.047 | N14: 2.35 | O14: 77 | P14: OK | Q14: 0.08 | R14: 0.076 | S14: 30.921053 | T14: -0.59842789 | U14: -0.56790841 | V14: 0 | W14: =IF(N(Q14)=0,"",Q14+IF(I14="yes",Q14*Inputs!$B$10*Inputs!$B$9,0)+V14) -> 0.076 | X14: =IF(OR(N(W14)<=0,N(N14)=0,N(L14)=0),"",MIN(L14,N14/W14)) -> 30.921053 | Y14: =IF(OR(X14="",N(O14)=0),"",X14/O14-1) -> -0.59842789 | Z14: =IF(OR(Y14="",N(O14)=0),"",Y14+N14/O14) -> -0.56790841 | AA14: =IF(OR(Z14="",N(U14)=0),"",Z14-U14) -> 0 | AB14: =IF(N(Q14)=0,"",Q14+IF(I14="yes",Q14*Inputs!$B$10*Inputs!$B$9,0)+IFERROR(INDEX(Inputs!$B$13:$B$15,MATCH(G14,Inputs!$A$13:$A$15,0)),0)+IFERROR(INDEX(Inputs!$B$18:$B$24,MATCH(H14,Inputs!$A$18:$A$24,0)),0)) -> 0.076 | AC14: =IF(OR(N(AB14)<=0,N(N14)=0,N(L14)=0),"",MIN(L14,N14/AB14)) -> 30.921053 | AD14: =IF(OR(AC14="",N(O14)=0),"",AC14/O14-1) -> -0.59842789 | AE14: =IF(OR(AD14="",N(O14)=0),"",AD14+N14/O14) -> -0.56790841 | AF14: =IF(OR(AE14="",N(Z14)=0),"",AE14-Z14) -> 0 | AG14: =IF(AND(N(M14)>0,N(L14)>0),M14*L14,N14) -> 2.35 | AH14: =IF(OR(N(AB14)<=0,N(AG14)=0,N(L14)=0),"",MIN(L14,AG14/AB14)) -> 30.921053 | AI14: =IF(OR(AH14="",N(O14)=0),"",AH14/O14-1) -> -0.59842789 | AJ14: =IF(OR(AI14="",N(O14)=0),"",AI14+AG14/O14) -> -0.56790841 | AK14: =IF(OR(AJ14="",N(AE14)=0),"",AJ14-AE14) -> 0 | AL14: =IF(N(F14)=0,"",INDEX(Inputs!$B$28:$B$32,IFERROR(MATCH(F14,Inputs!$A$28:$A$32,1),0)+1)) -> 0.075 | AN14: =IF(N(AM14)>0,AM14,AL14) -> 0.075 | AO14: =IF(N(AN14)=0,"",AN14+IF(I14="yes",AN14*Inputs!$B$10*Inputs!$B$9,0)+IFERROR(INDEX(Inputs!$B$13:$B$15,MATCH(G14,Inputs!$A$13:$A$15,0)),0)+IFERROR(INDEX(Inputs!$B$18:$B$24,MATCH(H14,Inputs!$A$18:$A$24,0)),0)) -> 0.07125 | AP14: =IF(OR(N(AO14)<=0,N(AG14)=0,N(L14)=0),"",MIN(L14,AG14/AO14)) -> 32.982456 | AQ14: =IF(OR(AP14="",N(O14)=0),"",AP14/O14-1) -> -0.57165641 | AR14: =IF(OR(AQ14="",N(O14)=0),"",AQ14+AG14/O14) -> -0.54113693 | AS14: =IF(OR(AR14="",N(AJ14)=0),"",AR14-AJ14) -> 0.026771474 | AT14: 100 | AU14: 4.7 | AV14: =IF(N(AT14)>0,AT14,L14) -> 100 | AW14: =IF(AND(N(M14)>0,N(AV14)>0),M14*AV14,IF(N(AU14)>0,AU14,N14)) -> 4.7 | AX14: =IF(N(AN14)=0,"",AN14+IF(I14="yes",AN14*Inputs!$B$10*Inputs!$B$9,0)+IFERROR(INDEX(Inputs!$B$13:$B$15,MATCH(G14,Inputs!$A$13:$A$15,0)),0)+IFERROR(INDEX(Inputs!$B$18:$B$24,MATCH(H14,Inputs!$A$18:$A$24,0)),0)) -> 0.07125 | AY14: =IF(OR(N(AX14)<=0,N(AW14)=0,N(AV14)=0),"",MIN(AV14,AW14/AX14)) -> 65.964912 | AZ14: =IF(OR(AY14="",N(O14)=0),"",AY14/O14-1) -> -0.14331283 | BA14: =IF(OR(AZ14="",N(O14)=0),"",AZ14+AW14/O14) -> -0.082273866 | BB14: =IF(OR(BA14="",N(AR14)=0),"",BA14-AR14) -> 0.45886307 | BC14: =IF(OR(BA14="",N(U14)=0),"",BA14-U14) -> 0.48563454 | BD14: PAR MISMATCH
A15: A-C | B15: 34 | C15: AILIN | D15: AEE | E15: AMEREN CORP | F15: 30100 | G15: PREFERRED | H15: FIXED | I15: yes | J15: Q | K15: 4 | L15: 50 | M15: 0.0442 | N15: 2.21 | O15: 71 | P15: OK | Q15: 0.08 | R15: 0.076 | S15: 29.078947 | T15: -0.59043736 | U15: -0.5593106 | V15: 0 | W15: =IF(N(Q15)=0,"",Q15+IF(I15="yes",Q15*Inputs!$B$10*Inputs!$B$9,0)+V15) -> 0.076 | X15: =IF(OR(N(W15)<=0,N(N15)=0,N(L15)=0),"",MIN(L15,N15/W15)) -> 29.078947 | Y15: =IF(OR(X15="",N(O15)=0),"",X15/O15-1) -> -0.59043736 | Z15: =IF(OR(Y15="",N(O15)=0),"",Y15+N15/O15) -> -0.5593106 | AA15: =IF(OR(Z15="",N(U15)=0),"",Z15-U15) -> 0 | AB15: =IF(N(Q15)=0,"",Q15+IF(I15="yes",Q15*Inputs!$B$10*Inputs!$B$9,0)+IFERROR(INDEX(Inputs!$B$13:$B$15,MATCH(G15,Inputs!$A$13:$A$15,0)),0)+IFERROR(INDEX(Inputs!$B$18:$B$24,MATCH(H15,Inputs!$A$18:$A$24,0)),0)) -> 0.076 | AC15: =IF(OR(N(AB15)<=0,N(N15)=0,N(L15)=0),"",MIN(L15,N15/AB15)) -> 29.078947 | AD15: =IF(OR(AC15="",N(O15)=0),"",AC15/O15-1) -> -0.59043736 | AE15: =IF(OR(AD15="",N(O15)=0),"",AD15+N15/O15) -> -0.5593106 | AF15: =IF(OR(AE15="",N(Z15)=0),"",AE15-Z15) -> 0 | AG15: =IF(AND(N(M15)>0,N(L15)>0),M15*L15,N15) -> 2.21 | AH15: =IF(OR(N(AB15)<=0,N(AG15)=0,N(L15)=0),"",MIN(L15,AG15/AB15)) -> 29.078947 | AI15: =IF(OR(AH15="",N(O15)=0),"",AH15/O15-1) -> -0.59043736 | AJ15: =IF(OR(AI15="",N(O15)=0),"",AI15+AG15/O15) -> -0.5593106 | AK15: =IF(OR(AJ15="",N(AE15)=0),"",AJ15-AE15) -> 0 | AL15: =IF(N(F15)=0,"",INDEX(Inputs!$B$28:$B$32,IFERROR(MATCH(F15,Inputs!$A$28:$A$32,1),0)+1)) -> 0.075 | AN15: =IF(N(AM15)>0,AM15,AL15) -> 0.075 | AO15: =IF(N(AN15)=0,"",AN15+IF(I15="yes",AN15*Inputs!$B$10*Inputs!$B$9,0)+IFERROR(INDEX(Inputs!$B$13:$B$15,MATCH(G15,Inputs!$A$13:$A$15,0)),0)+IFERROR(INDEX(Inputs!$B$18:$B$24,MATCH(H15,Inputs!$A$18:$A$24,0)),0)) -> 0.07125 | AP15: =IF(OR(N(AO15)<=0,N(AG15)=0,N(L15)=0),"",MIN(L15,AG15/AO15)) -> 31.017544 | AQ15: =IF(OR(AP15="",N(O15)=0),"",AP15/O15-1) -> -0.56313319 | AR15: =IF(OR(AQ15="",N(O15)=0),"",AQ15+AG15/O15) -> -0.53200642 | AS15: =IF(OR(AR15="",N(AJ15)=0),"",AR15-AJ15) -> 0.027304176 | AT15: 100 | AU15: 4.42 | AV15: =IF(N(AT15)>0,AT15,L15) -> 100 | AW15: =IF(AND(N(M15)>0,N(AV15)>0),M15*AV15,IF(N(AU15)>0,AU15,N15)) -> 4.42 | AX15: =IF(N(AN15)=0,"",AN15+IF(I15="yes",AN15*Inputs!$B$10*Inputs!$B$9,0)+IFERROR(INDEX(Inputs!$B$13:$B$15,MATCH(G15,Inputs!$A$13:$A$15,0)),0)+IFERROR(INDEX(Inputs!$B$18:$B$24,MATCH(H15,Inputs!$A$18:$A$24,0)),0)) -> 0.07125 | AY15: =IF(OR(N(AX15)<=0,N(AW15)=0,N(AV15)=0),"",MIN(AV15,AW15/AX15)) -> 62.035088 | AZ15: =IF(OR(AY15="",N(O15)=0),"",AY15/O15-1) -> -0.12626637 | BA15: =IF(OR(AZ15="",N(O15)=0),"",AZ15+AW15/O15) -> -0.064012849 | BB15: =IF(OR(BA15="",N(AR15)=0),"",BA15-AR15) -> 0.46799358 | BC15: =IF(OR(BA15="",N(U15)=0),"",BA15-U15) -> 0.49529775 | BD15: PAR MISMATCH
A16: A-C | B16: 35 | C16: AILIO | D16: AEE | E16: AMEREN CORP | F16: 30100 | G16: PREFERRED | H16: FIXED | I16: yes | J16: Q | K16: 4 | L16: 50 | M16: 0.0426 | N16: 2.13 | O16: 69.825 | P16: OK | Q16: 0.08 | R16: 0.076 | S16: 28.026316 | T16: -0.59862061 | U16: -0.56811578 | V16: 0 | W16: =IF(N(Q16)=0,"",Q16+IF(I16="yes",Q16*Inputs!$B$10*Inputs!$B$9,0)+V16) -> 0.076 | X16: =IF(OR(N(W16)<=0,N(N16)=0,N(L16)=0),"",MIN(L16,N16/W16)) -> 28.026316 | Y16: =IF(OR(X16="",N(O16)=0),"",X16/O16-1) -> -0.59862061 | Z16: =IF(OR(Y16="",N(O16)=0),"",Y16+N16/O16) -> -0.56811578 | AA16: =IF(OR(Z16="",N(U16)=0),"",Z16-U16) -> 0 | AB16: =IF(N(Q16)=0,"",Q16+IF(I16="yes",Q16*Inputs!$B$10*Inputs!$B$9,0)+IFERROR(INDEX(Inputs!$B$13:$B$15,MATCH(G16,Inputs!$A$13:$A$15,0)),0)+IFERROR(INDEX(Inputs!$B$18:$B$24,MATCH(H16,Inputs!$A$18:$A$24,0)),0)) -> 0.076 | AC16: =IF(OR(N(AB16)<=0,N(N16)=0,N(L16)=0),"",MIN(L16,N16/AB16)) -> 28.026316 | AD16: =IF(OR(AC16="",N(O16)=0),"",AC16/O16-1) -> -0.59862061 | AE16: =IF(OR(AD16="",N(O16)=0),"",AD16+N16/O16) -> -0.56811578 | AF16: =IF(OR(AE16="",N(Z16)=0),"",AE16-Z16) -> 0 | AG16: =IF(AND(N(M16)>0,N(L16)>0),M16*L16,N16) -> 2.13 | AH16: =IF(OR(N(AB16)<=0,N(AG16)=0,N(L16)=0),"",MIN(L16,AG16/AB16)) -> 28.026316 | AI16: =IF(OR(AH16="",N(O16)=0),"",AH16/O16-1) -> -0.59862061 | AJ16: =IF(OR(AI16="",N(O16)=0),"",AI16+AG16/O16) -> -0.56811578 | AK16: =IF(OR(AJ16="",N(AE16)=0),"",AJ16-AE16) -> 0 | AL16: =IF(N(F16)=0,"",INDEX(Inputs!$B$28:$B$32,IFERROR(MATCH(F16,Inputs!$A$28:$A$32,1),0)+1)) -> 0.075 | AN16: =IF(N(AM16)>0,AM16,AL16) -> 0.075 | AO16: =IF(N(AN16)=0,"",AN16+IF(I16="yes",AN16*Inputs!$B$10*Inputs!$B$9,0)+IFERROR(INDEX(Inputs!$B$13:$B$15,MATCH(G16,Inputs!$A$13:$A$15,0)),0)+IFERROR(INDEX(Inputs!$B$18:$B$24,MATCH(H16,Inputs!$A$18:$A$24,0)),0)) -> 0.07125 | AP16: =IF(OR(N(AO16)<=0,N(AG16)=0,N(L16)=0),"",MIN(L16,AG16/AO16)) -> 29.894737 | AQ16: =IF(OR(AP16="",N(O16)=0),"",AP16/O16-1) -> -0.57186199 | AR16: =IF(OR(AQ16="",N(O16)=0),"",AQ16+AG16/O16) -> -0.54135715 | AS16: =IF(OR(AR16="",N(AJ16)=0),"",AR16-AJ16) -> 0.026758626 | AT16: 100 | AU16: 4.26 | AV16: =IF(N(AT16)>0,AT16,L16) -> 100 | AW16: =IF(AND(N(M16)>0,N(AV16)>0),M16*AV16,IF(N(AU16)>0,AU16,N16)) -> 4.26 | AX16: =IF(N(AN16)=0,"",AN16+IF(I16="yes",AN16*Inputs!$B$10*Inputs!$B$9,0)+IFERROR(INDEX(Inputs!$B$13:$B$15,MATCH(G16,Inputs!$A$13:$A$15,0)),0)+IFERROR(INDEX(Inputs!$B$18:$B$24,MATCH(H16,Inputs!$A$18:$A$24,0)),0)) -> 0.07125 | AY16: =IF(OR(N(AX16)<=0,N(AW16)=0,N(AV16)=0),"",MIN(AV16,AW16/AX16)) -> 59.789474 | AZ16: =IF(OR(AY16="",N(O16)=0),"",AY16/O16-1) -> -0.14372397 | BA16: =IF(OR(AZ16="",N(O16)=0),"",AZ16+AW16/O16) -> -0.082714305 | BB16: =IF(OR(BA16="",N(AR16)=0),"",BA16-AR16) -> 0.45864285 | BC16: =IF(OR(BA16="",N(U16)=0),"",BA16-U16) -> 0.48540147 | BD16: PAR MISMATCH
A17: A-C | B17: 36 | C17: AILIP | D17: AEE | E17: AMEREN CORP | F17: 30100 | G17: PREFERRED | H17: FIXED | I17: yes | J17: Q | K17: 4 | L17: 50 | M17: 0.042 | N17: 2.1 | O17: 67.3 | P17: OK | Q17: 0.08 | R17: 0.076 | S17: 27.631579 | T17: -0.58942676 | U17: -0.5582232 | V17: 0 | W17: =IF(N(Q17)=0,"",Q17+IF(I17="yes",Q17*Inputs!$B$10*Inputs!$B$9,0)+V17) -> 0.076 | X17: =IF(OR(N(W17)<=0,N(N17)=0,N(L17)=0),"",MIN(L17,N17/W17)) -> 27.631579 | Y17: =IF(OR(X17="",N(O17)=0),"",X17/O17-1) -> -0.58942676 | Z17: =IF(OR(Y17="",N(O17)=0),"",Y17+N17/O17) -> -0.5582232 | AA17: =IF(OR(Z17="",N(U17)=0),"",Z17-U17) -> 0 | AB17: =IF(N(Q17)=0,"",Q17+IF(I17="yes",Q17*Inputs!$B$10*Inputs!$B$9,0)+IFERROR(INDEX(Inputs!$B$13:$B$15,MATCH(G17,Inputs!$A$13:$A$15,0)),0)+IFERROR(INDEX(Inputs!$B$18:$B$24,MATCH(H17,Inputs!$A$18:$A$24,0)),0)) -> 0.076 | AC17: =IF(OR(N(AB17)<=0,N(N17)=0,N(L17)=0),"",MIN(L17,N17/AB17)) -> 27.631579 | AD17: =IF(OR(AC17="",N(O17)=0),"",AC17/O17-1) -> -0.58942676 | AE17: =IF(OR(AD17="",N(O17)=0),"",AD17+N17/O17) -> -0.5582232 | AF17: =IF(OR(AE17="",N(Z17)=0),"",AE17-Z17) -> 0 | AG17: =IF(AND(N(M17)>0,N(L17)>0),M17*L17,N17) -> 2.1 | AH17: =IF(OR(N(AB17)<=0,N(AG17)=0,N(L17)=0),"",MIN(L17,AG17/AB17)) -> 27.631579 | AI17: =IF(OR(AH17="",N(O17)=0),"",AH17/O17-1) -> -0.58942676 | AJ17: =IF(OR(AI17="",N(O17)=0),"",AI17+AG17/O17) -> -0.5582232 | AK17: =IF(OR(AJ17="",N(AE17)=0),"",AJ17-AE17) -> 0 | AL17: =IF(N(F17)=0,"",INDEX(Inputs!$B$28:$B$32,IFERROR(MATCH(F17,Inputs!$A$28:$A$32,1),0)+1)) -> 0.075 | AN17: =IF(N(AM17)>0,AM17,AL17) -> 0.075 | AO17: =IF(N(AN17)=0,"",AN17+IF(I17="yes",AN17*Inputs!$B$10*Inputs!$B$9,0)+IFERROR(INDEX(Inputs!$B$13:$B$15,MATCH(G17,Inputs!$A$13:$A$15,0)),0)+IFERROR(INDEX(Inputs!$B$18:$B$24,MATCH(H17,Inputs!$A$18:$A$24,0)),0)) -> 0.07125 | AP17: =IF(OR(N(AO17)<=0,N(AG17)=0,N(L17)=0),"",MIN(L17,AG17/AO17)) -> 29.473684 | AQ17: =IF(OR(AP17="",N(O17)=0),"",AP17/O17-1) -> -0.56205521 | AR17: =IF(OR(AQ17="",N(O17)=0),"",AQ17+AG17/O17) -> -0.53085165 | AS17: =IF(OR(AR17="",N(AJ17)=0),"",AR17-AJ17) -> 0.027371549 | AT17: 100 | AU17: 4.2 | AV17: =IF(N(AT17)>0,AT17,L17) -> 100 | AW17: =IF(AND(N(M17)>0,N(AV17)>0),M17*AV17,IF(N(AU17)>0,AU17,N17)) -> 4.2 | AX17: =IF(N(AN17)=0,"",AN17+IF(I17="yes",AN17*Inputs!$B$10*Inputs!$B$9,0)+IFERROR(INDEX(Inputs!$B$13:$B$15,MATCH(G17,Inputs!$A$13:$A$15,0)),0)+IFERROR(INDEX(Inputs!$B$18:$B$24,MATCH(H17,Inputs!$A$18:$A$24,0)),0)) -> 0.07125 | AY17: =IF(OR(N(AX17)<=0,N(AW17)=0,N(AV17)=0),"",MIN(AV17,AW17/AX17)) -> 58.947368 | AZ17: =IF(OR(AY17="",N(O17)=0),"",AY17/O17-1) -> -0.12411042 | BA17: =IF(OR(AZ17="",N(O17)=0),"",AZ17+AW17/O17) -> -0.061703292 | BB17: =IF(OR(BA17="",N(AR17)=0),"",BA17-AR17) -> 0.46914835 | BC17: =IF(OR(BA17="",N(U17)=0),"",BA17-U17) -> 0.4965199 | BD17: PAR MISMATCH
A18: A-C | B18: 37 | C18: AILLI | D18: AEE | E18: AMEREN CORP | F18: 30100 | G18: PREFERRED | H18: FIXED | I18: yes | J18: Q | K18: 4 | L18: 100 | M18: 0.0516 | N18: 5.16 | O18: 81 | P18: OK | Q18: 0.08 | R18: 0.076 | S18: 67.894737 | T18: -0.16179337 | U18: -0.098089669 | V18: 0 | W18: =IF(N(Q18)=0,"",Q18+IF(I18="yes",Q18*Inputs!$B$10*Inputs!$B$9,0)+V18) -> 0.076 | X18: =IF(OR(N(W18)<=0,N(N18)=0,N(L18)=0),"",MIN(L18,N18/W18)) -> 67.894737 | Y18: =IF(OR(X18="",N(O18)=0),"",X18/O18-1) -> -0.16179337 | Z18: =IF(OR(Y18="",N(O18)=0),"",Y18+N18/O18) -> -0.098089669 | AA18: =IF(OR(Z18="",N(U18)=0),"",Z18-U18) -> 0 | AB18: =IF(N(Q18)=0,"",Q18+IF(I18="yes",Q18*Inputs!$B$10*Inputs!$B$9,0)+IFERROR(INDEX(Inputs!$B$13:$B$15,MATCH(G18,Inputs!$A$13:$A$15,0)),0)+IFERROR(INDEX(Inputs!$B$18:$B$24,MATCH(H18,Inputs!$A$18:$A$24,0)),0)) -> 0.076 | AC18: =IF(OR(N(AB18)<=0,N(N18)=0,N(L18)=0),"",MIN(L18,N18/AB18)) -> 67.894737 | AD18: =IF(OR(AC18="",N(O18)=0),"",AC18/O18-1) -> -0.16179337 | AE18: =IF(OR(AD18="",N(O18)=0),"",AD18+N18/O18) -> -0.098089669 | AF18: =IF(OR(AE18="",N(Z18)=0),"",AE18-Z18) -> 0 | AG18: =IF(AND(N(M18)>0,N(L18)>0),M18*L18,N18) -> 5.16 | AH18: =IF(OR(N(AB18)<=0,N(AG18)=0,N(L18)=0),"",MIN(L18,AG18/AB18)) -> 67.894737 | AI18: =IF(OR(AH18="",N(O18)=0),"",AH18/O18-1) -> -0.16179337 | AJ18: =IF(OR(AI18="",N(O18)=0),"",AI18+AG18/O18) -> -0.098089669 | AK18: =IF(OR(AJ18="",N(AE18)=0),"",AJ18-AE18) -> 0 | AL18: =IF(N(F18)=0,"",INDEX(Inputs!$B$28:$B$32,IFERROR(MATCH(F18,Inputs!$A$28:$A$32,1),0)+1)) -> 0.075 | AN18: =IF(N(AM18)>0,AM18,AL18) -> 0.075 | AO18: =IF(N(AN18)=0,"",AN18+IF(I18="yes",AN18*Inputs!$B$10*Inputs!$B$9,0)+IFERROR(INDEX(Inputs!$B$13:$B$15,MATCH(G18,Inputs!$A$13:$A$15,0)),0)+IFERROR(INDEX(Inputs!$B$18:$B$24,MATCH(H18,Inputs!$A$18:$A$24,0)),0)) -> 0.07125 | AP18: =IF(OR(N(AO18)<=0,N(AG18)=0,N(L18)=0),"",MIN(L18,AG18/AO18)) -> 72.421053 | AQ18: =IF(OR(AP18="",N(O18)=0),"",AP18/O18-1) -> -0.10591293 | AR18: =IF(OR(AQ18="",N(O18)=0),"",AQ18+AG18/O18) -> -0.042209227 | AS18: =IF(OR(AR18="",N(AJ18)=0),"",AR18-AJ18) -> 0.055880442 | AT18: 100 | AU18: 5.16 | AV18: =IF(N(AT18)>0,AT18,L18) -> 100 | AW18: =IF(AND(N(M18)>0,N(AV18)>0),M18*AV18,IF(N(AU18)>0,AU18,N18)) -> 5.16 | AX18: =IF(N(AN18)=0,"",AN18+IF(I18="yes",AN18*Inputs!$B$10*Inputs!$B$9,0)+IFERROR(INDEX(Inputs!$B$13:$B$15,MATCH(G18,Inputs!$A$13:$A$15,0)),0)+IFERROR(INDEX(Inputs!$B$18:$B$24,MATCH(H18,Inputs!$A$18:$A$24,0)),0)) -> 0.07125 | AY18: =IF(OR(N(AX18)<=0,N(AW18)=0,N(AV18)=0),"",MIN(AV18,AW18/AX18)) -> 72.421053 | AZ18: =IF(OR(AY18="",N(O18)=0),"",AY18/O18-1) -> -0.10591293 | BA18: =IF(OR(AZ18="",N(O18)=0),"",AZ18+AW18/O18) -> -0.042209227 | BB18: =IF(OR(BA18="",N(AR18)=0),"",BA18-AR18) -> 0 | BC18: =IF(OR(BA18="",N(U18)=0),"",BA18-U18) -> 0.055880442
A19: A-C | B19: 38 | C19: AILLM | D19: AEE | E19: AMEREN CORP | F19: 30100 | G19: PREFERRED | H19: FIXED | I19: yes | J19: Q | K19: 4 | L19: 100 | M19: 0.0492 | N19: 4.92 | O19: 78.6 | P19: OK | Q19: 0.08 | R19: 0.076 | S19: 64.736842 | T19: -0.17637605 | U19: -0.11378063 | V19: 0 | W19: =IF(N(Q19)=0,"",Q19+IF(I19="yes",Q19*Inputs!$B$10*Inputs!$B$9,0)+V19) -> 0.076 | X19: =IF(OR(N(W19)<=0,N(N19)=0,N(L19)=0),"",MIN(L19,N19/W19)) -> 64.736842 | Y19: =IF(OR(X19="",N(O19)=0),"",X19/O19-1) -> -0.17637605 | Z19: =IF(OR(Y19="",N(O19)=0),"",Y19+N19/O19) -> -0.11378063 | AA19: =IF(OR(Z19="",N(U19)=0),"",Z19-U19) -> 0 | AB19: =IF(N(Q19)=0,"",Q19+IF(I19="yes",Q19*Inputs!$B$10*Inputs!$B$9,0)+IFERROR(INDEX(Inputs!$B$13:$B$15,MATCH(G19,Inputs!$A$13:$A$15,0)),0)+IFERROR(INDEX(Inputs!$B$18:$B$24,MATCH(H19,Inputs!$A$18:$A$24,0)),0)) -> 0.076 | AC19: =IF(OR(N(AB19)<=0,N(N19)=0,N(L19)=0),"",MIN(L19,N19/AB19)) -> 64.736842 | AD19: =IF(OR(AC19="",N(O19)=0),"",AC19/O19-1) -> -0.17637605 | AE19: =IF(OR(AD19="",N(O19)=0),"",AD19+N19/O19) -> -0.11378063 | AF19: =IF(OR(AE19="",N(Z19)=0),"",AE19-Z19) -> 0 | AG19: =IF(AND(N(M19)>0,N(L19)>0),M19*L19,N19) -> 4.92 | AH19: =IF(OR(N(AB19)<=0,N(AG19)=0,N(L19)=0),"",MIN(L19,AG19/AB19)) -> 64.736842 | AI19: =IF(OR(AH19="",N(O19)=0),"",AH19/O19-1) -> -0.17637605 | AJ19: =IF(OR(AI19="",N(O19)=0),"",AI19+AG19/O19) -> -0.11378063 | AK19: =IF(OR(AJ19="",N(AE19)=0),"",AJ19-AE19) -> 0 | AL19: =IF(N(F19)=0,"",INDEX(Inputs!$B$28:$B$32,IFERROR(MATCH(F19,Inputs!$A$28:$A$32,1),0)+1)) -> 0.075 | AN19: =IF(N(AM19)>0,AM19,AL19) -> 0.075 | AO19: =IF(N(AN19)=0,"",AN19+IF(I19="yes",AN19*Inputs!$B$10*Inputs!$B$9,0)+IFERROR(INDEX(Inputs!$B$13:$B$15,MATCH(G19,Inputs!$A$13:$A$15,0)),0)+IFERROR(INDEX(Inputs!$B$18:$B$24,MATCH(H19,Inputs!$A$18:$A$24,0)),0)) -> 0.07125 | AP19: =IF(OR(N(AO19)<=0,N(AG19)=0,N(L19)=0),"",MIN(L19,AG19/AO19)) -> 69.052632 | AQ19: =IF(OR(AP19="",N(O19)=0),"",AP19/O19-1) -> -0.12146779 | AR19: =IF(OR(AQ19="",N(O19)=0),"",AQ19+AG19/O19) -> -0.058872372 | AS19: =IF(OR(AR19="",N(AJ19)=0),"",AR19-AJ19) -> 0.054908263 | AT19: 100 | AU19: 4.92 | AV19: =IF(N(AT19)>0,AT19,L19) -> 100 | AW19: =IF(AND(N(M19)>0,N(AV19)>0),M19*AV19,IF(N(AU19)>0,AU19,N19)) -> 4.92 | AX19: =IF(N(AN19)=0,"",AN19+IF(I19="yes",AN19*Inputs!$B$10*Inputs!$B$9,0)+IFERROR(INDEX(Inputs!$B$13:$B$15,MATCH(G19,Inputs!$A$13:$A$15,0)),0)+IFERROR(INDEX(Inputs!$B$18:$B$24,MATCH(H19,Inputs!$A$18:$A$24,0)),0)) -> 0.07125 | AY19: =IF(OR(N(AX19)<=0,N(AW19)=0,N(AV19)=0),"",MIN(AV19,AW19/AX19)) -> 69.052632 | AZ19: =IF(OR(AY19="",N(O19)=0),"",AY19/O19-1) -> -0.12146779 | BA19: =IF(OR(AZ19="",N(O19)=0),"",AZ19+AW19/O19) -> -0.058872372 | BB19: =IF(OR(BA19="",N(AR19)=0),"",BA19-AR19) -> 0 | BC19: =IF(OR(BA19="",N(U19)=0),"",BA19-U19) -> 0.054908263
A20: A-C | B20: 39 | C20: AILLN | D20: AEE | E20: AMEREN CORP | F20: 30100 | G20: PREFERRED | H20: FIXED | I20: yes | J20: Q | K20: 4 | L20: 100 | M20: 0.049 | N20: 4.9 | O20: 77.66 | P20: OK | Q20: 0.08 | R20: 0.076 | S20: 64.473684 | T20: -0.16979546 | U20: -0.10669992 | V20: 0 | W20: =IF(N(Q20)=0,"",Q20+IF(I20="yes",Q20*Inputs!$B$10*Inputs!$B$9,0)+V20) -> 0.076 | X20: =IF(OR(N(W20)<=0,N(N20)=0,N(L20)=0),"",MIN(L20,N20/W20)) -> 64.473684 | Y20: =IF(OR(X20="",N(O20)=0),"",X20/O20-1) -> -0.16979546 | Z20: =IF(OR(Y20="",N(O20)=0),"",Y20+N20/O20) -> -0.10669992 | AA20: =IF(OR(Z20="",N(U20)=0),"",Z20-U20) -> 0 | AB20: =IF(N(Q20)=0,"",Q20+IF(I20="yes",Q20*Inputs!$B$10*Inputs!$B$9,0)+IFERROR(INDEX(Inputs!$B$13:$B$15,MATCH(G20,Inputs!$A$13:$A$15,0)),0)+IFERROR(INDEX(Inputs!$B$18:$B$24,MATCH(H20,Inputs!$A$18:$A$24,0)),0)) -> 0.076 | AC20: =IF(OR(N(AB20)<=0,N(N20)=0,N(L20)=0),"",MIN(L20,N20/AB20)) -> 64.473684 | AD20: =IF(OR(AC20="",N(O20)=0),"",AC20/O20-1) -> -0.16979546 | AE20: =IF(OR(AD20="",N(O20)=0),"",AD20+N20/O20) -> -0.10669992 | AF20: =IF(OR(AE20="",N(Z20)=0),"",AE20-Z20) -> 0 | AG20: =IF(AND(N(M20)>0,N(L20)>0),M20*L20,N20) -> 4.9 | AH20: =IF(OR(N(AB20)<=0,N(AG20)=0,N(L20)=0),"",MIN(L20,AG20/AB20)) -> 64.473684 | AI20: =IF(OR(AH20="",N(O20)=0),"",AH20/O20-1) -> -0.16979546 | AJ20: =IF(OR(AI20="",N(O20)=0),"",AI20+AG20/O20) -> -0.10669992 | AK20: =IF(OR(AJ20="",N(AE20)=0),"",AJ20-AE20) -> 0 | AL20: =IF(N(F20)=0,"",INDEX(Inputs!$B$28:$B$32,IFERROR(MATCH(F20,Inputs!$A$28:$A$32,1),0)+1)) -> 0.075 | AN20: =IF(N(AM20)>0,AM20,AL20) -> 0.075 | AO20: =IF(N(AN20)=0,"",AN20+IF(I20="yes",AN20*Inputs!$B$10*Inputs!$B$9,0)+IFERROR(INDEX(Inputs!$B$13:$B$15,MATCH(G20,Inputs!$A$13:$A$15,0)),0)+IFERROR(INDEX(Inputs!$B$18:$B$24,MATCH(H20,Inputs!$A$18:$A$24,0)),0)) -> 0.07125 | AP20: =IF(OR(N(AO20)<=0,N(AG20)=0,N(L20)=0),"",MIN(L20,AG20/AO20)) -> 68.77193 | AQ20: =IF(OR(AP20="",N(O20)=0),"",AP20/O20-1) -> -0.1144485 | AR20: =IF(OR(AQ20="",N(O20)=0),"",AQ20+AG20/O20) -> -0.051352951 | AS20: =IF(OR(AR20="",N(AJ20)=0),"",AR20-AJ20) -> 0.055346969 | AT20: 100 | AU20: 4.9 | AV20: =IF(N(AT20)>0,AT20,L20) -> 100 | AW20: =IF(AND(N(M20)>0,N(AV20)>0),M20*AV20,IF(N(AU20)>0,AU20,N20)) -> 4.9 | AX20: =IF(N(AN20)=0,"",AN20+IF(I20="yes",AN20*Inputs!$B$10*Inputs!$B$9,0)+IFERROR(INDEX(Inputs!$B$13:$B$15,MATCH(G20,Inputs!$A$13:$A$15,0)),0)+IFERROR(INDEX(Inputs!$B$18:$B$24,MATCH(H20,Inputs!$A$18:$A$24,0)),0)) -> 0.07125 | AY20: =IF(OR(N(AX20)<=0,N(AW20)=0,N(AV20)=0),"",MIN(AV20,AW20/AX20)) -> 68.77193 | AZ20: =IF(OR(AY20="",N(O20)=0),"",AY20/O20-1) -> -0.1144485 | BA20: =IF(OR(AZ20="",N(O20)=0),"",AZ20+AW20/O20) -> -0.051352951 | BB20: =IF(OR(BA20="",N(AR20)=0),"",BA20-AR20) -> 0 | BC20: =IF(OR(BA20="",N(U20)=0),"",BA20-U20) -> 0.055346969
A21: A-C | B21: 40 | C21: AILLO | D21: AEE | E21: AMEREN CORP | F21: 30100 | G21: PREFERRED | H21: FIXED | I21: yes | J21: Q | K21: 4 | L21: 100 | M21: 0.0425 | N21: 4.25 | O21: 67.5 | P21: OK | Q21: 0.08 | R21: 0.076 | S21: 55.921053 | T21: -0.17153996 | U21: -0.108577 | V21: 0 | W21: =IF(N(Q21)=0,"",Q21+IF(I21="yes",Q21*Inputs!$B$10*Inputs!$B$9,0)+V21) -> 0.076 | X21: =IF(OR(N(W21)<=0,N(N21)=0,N(L21)=0),"",MIN(L21,N21/W21)) -> 55.921053 | Y21: =IF(OR(X21="",N(O21)=0),"",X21/O21-1) -> -0.17153996 | Z21: =IF(OR(Y21="",N(O21)=0),"",Y21+N21/O21) -> -0.108577 | AA21: =IF(OR(Z21="",N(U21)=0),"",Z21-U21) -> 0 | AB21: =IF(N(Q21)=0,"",Q21+IF(I21="yes",Q21*Inputs!$B$10*Inputs!$B$9,0)+IFERROR(INDEX(Inputs!$B$13:$B$15,MATCH(G21,Inputs!$A$13:$A$15,0)),0)+IFERROR(INDEX(Inputs!$B$18:$B$24,MATCH(H21,Inputs!$A$18:$A$24,0)),0)) -> 0.076 | AC21: =IF(OR(N(AB21)<=0,N(N21)=0,N(L21)=0),"",MIN(L21,N21/AB21)) -> 55.921053 | AD21: =IF(OR(AC21="",N(O21)=0),"",AC21/O21-1) -> -0.17153996 | AE21: =IF(OR(AD21="",N(O21)=0),"",AD21+N21/O21) -> -0.108577 | AF21: =IF(OR(AE21="",N(Z21)=0),"",AE21-Z21) -> 0 | AG21: =IF(AND(N(M21)>0,N(L21)>0),M21*L21,N21) -> 4.25 | AH21: =IF(OR(N(AB21)<=0,N(AG21)=0,N(L21)=0),"",MIN(L21,AG21/AB21)) -> 55.921053 | AI21: =IF(OR(AH21="",N(O21)=0),"",AH21/O21-1) -> -0.17153996 | AJ21: =IF(OR(AI21="",N(O21)=0),"",AI21+AG21/O21) -> -0.108577 | AK21: =IF(OR(AJ21="",N(AE21)=0),"",AJ21-AE21) -> 0 | AL21: =IF(N(F21)=0,"",INDEX(Inputs!$B$28:$B$32,IFERROR(MATCH(F21,Inputs!$A$28:$A$32,1),0)+1)) -> 0.075 | AN21: =IF(N(AM21)>0,AM21,AL21) -> 0.075 | AO21: =IF(N(AN21)=0,"",AN21+IF(I21="yes",AN21*Inputs!$B$10*Inputs!$B$9,0)+IFERROR(INDEX(Inputs!$B$13:$B$15,MATCH(G21,Inputs!$A$13:$A$15,0)),0)+IFERROR(INDEX(Inputs!$B$18:$B$24,MATCH(H21,Inputs!$A$18:$A$24,0)),0)) -> 0.07125 | AP21: =IF(OR(N(AO21)<=0,N(AG21)=0,N(L21)=0),"",MIN(L21,AG21/AO21)) -> 59.649123 | AQ21: =IF(OR(AP21="",N(O21)=0),"",AP21/O21-1) -> -0.11630929 | AR21: =IF(OR(AQ21="",N(O21)=0),"",AQ21+AG21/O21) -> -0.053346329 | AS21: =IF(OR(AR21="",N(AJ21)=0),"",AR21-AJ21) -> 0.055230669 | AT21: 100 | AU21: 4.25 | AV21: =IF(N(AT21)>0,AT21,L21) -> 100 | AW21: =IF(AND(N(M21)>0,N(AV21)>0),M21*AV21,IF(N(AU21)>0,AU21,N21)) -> 4.25 | AX21: =IF(N(AN21)=0,"",AN21+IF(I21="yes",AN21*Inputs!$B$10*Inputs!$B$9,0)+IFERROR(INDEX(Inputs!$B$13:$B$15,MATCH(G21,Inputs!$A$13:$A$15,0)),0)+IFERROR(INDEX(Inputs!$B$18:$B$24,MATCH(H21,Inputs!$A$18:$A$24,0)),0)) -> 0.07125 | AY21: =IF(OR(N(AX21)<=0,N(AW21)=0,N(AV21)=0),"",MIN(AV21,AW21/AX21)) -> 59.649123 | AZ21: =IF(OR(AY21="",N(O21)=0),"",AY21/O21-1) -> -0.11630929 | BA21: =IF(OR(AZ21="",N(O21)=0),"",AZ21+AW21/O21) -> -0.053346329 | BB21: =IF(OR(BA21="",N(AR21)=0),"",BA21-AR21) -> 0 | BC21: =IF(OR(BA21="",N(U21)=0),"",BA21-U21) -> 0.055230669
A22: A-C | B22: 41 | C22: AILLP | D22: AEE | E22: AMEREN CORP | F22: 30100 | G22: PREFERRED | H22: FIXED | I22: yes | J22: Q | K22: 4 | L22: 100 | M22: 0.04 | N22: 4 | O22: 62.75 | P22: OK | Q22: 0.08 | R22: 0.076 | S22: 52.631579 | T22: -0.16124974 | U22: -0.097504718 | V22: 0 | W22: =IF(N(Q22)=0,"",Q22+IF(I22="yes",Q22*Inputs!$B$10*Inputs!$B$9,0)+V22) -> 0.076 | X22: =IF(OR(N(W22)<=0,N(N22)=0,N(L22)=0),"",MIN(L22,N22/W22)) -> 52.631579 | Y22: =IF(OR(X22="",N(O22)=0),"",X22/O22-1) -> -0.16124974 | Z22: =IF(OR(Y22="",N(O22)=0),"",Y22+N22/O22) -> -0.097504718 | AA22: =IF(OR(Z22="",N(U22)=0),"",Z22-U22) -> 0 | AB22: =IF(N(Q22)=0,"",Q22+IF(I22="yes",Q22*Inputs!$B$10*Inputs!$B$9,0)+IFERROR(INDEX(Inputs!$B$13:$B$15,MATCH(G22,Inputs!$A$13:$A$15,0)),0)+IFERROR(INDEX(Inputs!$B$18:$B$24,MATCH(H22,Inputs!$A$18:$A$24,0)),0)) -> 0.076 | AC22: =IF(OR(N(AB22)<=0,N(N22)=0,N(L22)=0),"",MIN(L22,N22/AB22)) -> 52.631579 | AD22: =IF(OR(AC22="",N(O22)=0),"",AC22/O22-1) -> -0.16124974 | AE22: =IF(OR(AD22="",N(O22)=0),"",AD22+N22/O22) -> -0.097504718 | AF22: =IF(OR(AE22="",N(Z22)=0),"",AE22-Z22) -> 0 | AG22: =IF(AND(N(M22)>0,N(L22)>0),M22*L22,N22) -> 4 | AH22: =IF(OR(N(AB22)<=0,N(AG22)=0,N(L22)=0),"",MIN(L22,AG22/AB22)) -> 52.631579 | AI22: =IF(OR(AH22="",N(O22)=0),"",AH22/O22-1) -> -0.16124974 | AJ22: =IF(OR(AI22="",N(O22)=0),"",AI22+AG22/O22) -> -0.097504718 | AK22: =IF(OR(AJ22="",N(AE22)=0),"",AJ22-AE22) -> 0 | AL22: =IF(N(F22)=0,"",INDEX(Inputs!$B$28:$B$32,IFERROR(MATCH(F22,Inputs!$A$28:$A$32,1),0)+1)) -> 0.075 | AN22: =IF(N(AM22)>0,AM22,AL22) -> 0.075 | AO22: =IF(N(AN22)=0,"",AN22+IF(I22="yes",AN22*Inputs!$B$10*Inputs!$B$9,0)+IFERROR(INDEX(Inputs!$B$13:$B$15,MATCH(G22,Inputs!$A$13:$A$15,0)),0)+IFERROR(INDEX(Inputs!$B$18:$B$24,MATCH(H22,Inputs!$A$18:$A$24,0)),0)) -> 0.07125 | AP22: =IF(OR(N(AO22)<=0,N(AG22)=0,N(L22)=0),"",MIN(L22,AG22/AO22)) -> 56.140351 | AQ22: =IF(OR(AP22="",N(O22)=0),"",AP22/O22-1) -> -0.10533305 | AR22: =IF(OR(AQ22="",N(O22)=0),"",AQ22+AG22/O22) -> -0.041588034 | AS22: =IF(OR(AR22="",N(AJ22)=0),"",AR22-AJ22) -> 0.055916684 | AT22: 100 | AU22: 4 | AV22: =IF(N(AT22)>0,AT22,L22) -> 100 | AW22: =IF(AND(N(M22)>0,N(AV22)>0),M22*AV22,IF(N(AU22)>0,AU22,N22)) -> 4 | AX22: =IF(N(AN22)=0,"",AN22+IF(I22="yes",AN22*Inputs!$B$10*Inputs!$B$9,0)+IFERROR(INDEX(Inputs!$B$13:$B$15,MATCH(G22,Inputs!$A$13:$A$15,0)),0)+IFERROR(INDEX(Inputs!$B$18:$B$24,MATCH(H22,Inputs!$A$18:$A$24,0)),0)) -> 0.07125 | AY22: =IF(OR(N(AX22)<=0,N(AW22)=0,N(AV22)=0),"",MIN(AV22,AW22/AX22)) -> 56.140351 | AZ22: =IF(OR(AY22="",N(O22)=0),"",AY22/O22-1) -> -0.10533305 | BA22: =IF(OR(AZ22="",N(O22)=0),"",AZ22+AW22/O22) -> -0.041588034 | BB22: =IF(OR(BA22="",N(AR22)=0),"",BA22-AR22) -> 0 | BC22: =IF(OR(BA22="",N(U22)=0),"",BA22-U22) -> 0.055916684
